Workbook
Name LTE: #REF!

Sheet Thông tin xe
A4: 车头：桂FB3272
A5: 拖挂：赣L3858挂
A6: 柜号:
A7: 车型：18.6米大版 | I7: Tổng | J7: 35700
A8: 车厢长18.6米宽3米 | I8: TTP
A9: 车头颜色：红色 | I9: Giang minh | J9: 1120
A10: 备案号： | I10: KTT | J10: 8670
A11: 司机姓名：小刘 | J11: =J7-J9-J10 -> 25910
A12: 电话：18177720051

Sheet HỢP ĐỒNG
A1: HỢP ĐỒNG NGOẠI THƯƠNG | H1: Số hợp đồng: | I1: 0902
A2: ="Số: "&I1&"GF-TH/26" -> Số: 0902 GF-TH/26 | H2: Ngày hợp đồng: | I2: 46270 | L2: =I1&"/19NK-CM" -> 0902 /19NK-CM
C4: ="Hôm nay, ngày "&DAY(I2)&" tháng "&MONTH(I2)&" năm "&YEAR(I2)&" chúng tôi gồm có:" -> Hôm nay, ngày 5 tháng 9 năm 2026 chúng tôi gồm có: | I4: \
C5: BÊN A : PINGXIANG GUIFENG TRADING CO.,LTD
C6: Địa chỉ: NO.6 PHASE II PAVEMENT BAIYUN FIELD TIANNAN SECONDARY PINGXIANG CITY GUANGXI CHINA
C7: Tài khoản ngân hàng số: 800127856500015 tại ngân hàng GUANGXI BEIBU GULF BANK SWIFT code: BGBKCNBJ
C8: Điện thoại: +86-18154645304
C9: Người đại diện: NONG RUN RONG | D9: Chức vụ: Giám đốc
C10: BÊN B: CÔNG TY TNHH THƯƠNG MẠI VÀ XUẤT NHẬP KHẨU TRƯỜNG HẢI
C11: Trụ sở: Số 12 Đường Phụ Số 4, Khu đô thị Phú Lộc 2, Phường Kỳ Lừa, Tỉnh Lạng Sơn, Việt Nam
C12: Mã số thuế: 4900944167 | L12: 25880
C13: Tài khoản ngân hàng số: 9328666888 – Ngân hàng Thương mại Cổ phần Quân đội - CN Tây Hà Nội
C14: Người đại diện: ĐƯỜNG ANH TUẤN | D14: Chức vụ: Giám đốc
C15: Hai bên bàn bạc, thống nhất ý kiến. Bên A đồng ý bán cho bên B lô hàng theo danh mục chi tiết hàng hóa và các điều khoản trong nội dung hợp đồng như sau:
C16: ĐIỀU 1: TÊN HÀNG, SỐ LƯỢNG, GIÁ CẢ | H16: 25844
A18: STT | B18: Mã Hàng | C18: Tên hàng hóa | D18: ĐVT | E18: Số lượng | F18: Đơn giá (USD) | G18: Thành tiền (USD) | H18: Mã biểu thuế ưu đãi | I18: Mã HS | J18: Trị giá | K18: HĐ | L18: Giá tính thuế NK | M18: TS nhập khẩu sau khi có C/O | N18: Thuế NK | O18: Giá tính thuế GTGT | P18: Thuế suất GTGT | Q18: Thuế GTGT | R18: DT đã có lãi | S18: Giá /cân | T18: Trị giá tính thuế CBPG | U18: Thuế suất CBPG | V18: Thuế CBPG
A19: 1 | B19: CN082822-10HN | C19: Khăn lau bụi dùng để lau xe hơi, chất liệu vải dệt kim từ sợi polyester, KT:(30*30)cm, không hiệu, NSX: Qingdao Tao Hui Industrial. Mới 100% | D19: PCE | E19: 20000 | F19: 0.094 | G19: =E19*F19 -> 1880 | H19: B05 | I19: 63071090 | J19: =F19*$L$12 -> 2432.72 | K19: 2500 | L19: =G19*$L$12 -> 48654400 | M19: 0 | N19: =M19*L19 -> 0 | O19: =L19+N19 -> 48654400 | P19: 0.08 | Q19: =O19*P19 -> 3892352 | R19: 115 | S19: =G19/R19 -> 16.347826 | T19: =L19 -> 48654400 | U19: 0 | V19: =T19*U19 -> 0 | W19: 1634 | X19: =G19-W19 -> 246
A20: 2 | B20: CN090109-1HN | C20: Bộ ấm chén pha trà bằng gốm đất nung tráng men rạn Nhữ Diêu,gồm ấm trà dung tích 250ml,chén khải 190ml và chén uống trà 50ml, đóng hộp quà tặng, không hiệu. NSX: Shenzhen Tao Hui Industrial. Mới 100% | D20: SET | E20: 20 | F20: 5.16 | G20: =E20*F20 -> 103.2 | I20: 69120000 | J20: =F20*$L$12 -> 133540.8 | K20: 136880 | L20: =G20*$L$12 -> 2670816 | M20: 0 | N20: =M20*L20 -> 0 | O20: =L20+N20 -> 2670816 | P20: 0.08 | Q20: =O20*P20 -> 213665.28 | R20: 116 | S20: =G20/R20 -> 0.88965517 | T20: =L20 -> 2670816 | U20: 0 | V20: =T20*U20 -> 0 | W20: 360 | X20: =G20-W20 -> -256.8
A21: 3 | C21: Bộ ấm chén pha trà du lịch bằng gốm đất nung tráng men trắng, dáng Tây Thi họa tiết Núi Non, gồm ấm trà dung tích 270ml, tống trà 150ml, chén trà 50ml,đóng hộp quà tặng, không hiệu, Mới 100% | D21: SET | E21: 20 | F21: 4.09 | G21: =E21*F21 -> 81.8 | I21: 69120000 | J21: =F21*$L$12 -> 105849.2 | K21: 108560 | L21: =G21*$L$12 -> 2116984 | M21: 0 | N21: =M21*L21 -> 0 | O21: =L21+N21 -> 2116984 | P21: 0.08 | Q21: =O21*P21 -> 169358.72 | R21: 117 | S21: =G21/R21 -> 0.6991453 | T21: =L21 -> 2116984 | U21: 0 | V21: =T21*U21 -> 0 | W21: 1117.8 | X21: =G21-W21 -> -1036
A22: 4 | C22: Bộ ấm chén trà bằng gốm đất nung, kiểu dáng Nhật gồm 1 ấm 200ml và 4 chén 60ml kèm hộp quà tặng, không hiệu, NSX: Shenzhen Tao Hui Industrial Co., Ltd., Mới 100% | D22: SET | E22: 50 | F22: 5.69 | G22: =E22*F22 -> 284.5 | I22: 69120000 | J22: =F22*$L$12 -> 147257.2 | K22: 151040 | L22: =G22*$L$12 -> 7362860 | M22: 0 | N22: =M22*L22 -> 0 | O22: =L22+N22 -> 7362860 | P22: 0.08 | Q22: =O22*P22 -> 589028.8 | R22: 118 | S22: =G22/R22 -> 2.4110169 | T22: =L22 -> 7362860 | U22: 0 | V22: =T22*U22 -> 0 | W22: 297.2 | X22: =G22-W22 -> -12.7
A23: 5 | B23: CN083010-1HN | C23: Ấm pha trà bằng gốm đất nung không tráng men (Tử Sa) dáng Hán Ngõa, màu xanh Lục Nê, dung tích 240ml, không dùng điện, không hiệu, NSX: Shenzhen Tao Hui Industrial Co., Ltd., Mới 100% | D23: PCE | E23: 10 | F23: 13.6 | G23: =E23*F23 -> 136 | I23: 69120000 | J23: =F23*$L$12 -> 351968 | K23: 360797 | L23: =G23*$L$12 -> 3519680 | M23: 0 | N23: =M23*L23 -> 0 | O23: =L23+N23 -> 3519680 | P23: 0.08 | Q23: =O23*P23 -> 281574.4 | R23: 119 | S23: =G23/R23 -> 1.1428571 | T23: =L23 -> 3519680 | U23: 0 | V23: =T23*U23 -> 0 | W23: 393 | X23: =G23-W23 -> -257
A24: 6 | C24: Ấm pha trà bằng gốm đất nung không tráng men (Tử Sa) dáng Tây Thi, màu đỏ Đại Hồng Bào, dung tích 240ml, không dùng điện, không hiệu, NSX: Shenzhen Tao Hui Industrial Co., Ltd., Mới 100% | D24: PCE | E24: 15 | F24: 10.46 | G24: =E24*F24 -> 156.9 | I24: 69120000 | J24: =F24*$L$12 -> 270704.8 | K24: 277536 | L24: =G24*$L$12 -> 4060572 | M24: 0 | N24: =M24*L24 -> 0 | O24: =L24+N24 -> 4060572 | P24: 0.08 | Q24: =O24*P24 -> 324845.76 | R24: 120 | S24: =G24/R24 -> 1.3075 | T24: =L24 -> 4060572 | U24: 0 | V24: =T24*U24 -> 0 | W24: 1038.2 | X24: =G24-W24 -> -881.3
A25: 7 | C25: Cốc uống trà bằng gốm đất nung không tráng men (Tử Sa) họa tiết Thiên Hương, dung tích 180ml, không hiệu, NSX: Shenzhen Tao Hui Industrial Co., Ltd., Mới 100% | D25: PCE | E25: 20 | F25: 4.49 | G25: =E25*F25 -> 89.8 | I25: 69120000 | J25: =F25*$L$12 -> 116201.2 | K25: 119227 | L25: =G25*$L$12 -> 2324024 | M25: 0 | N25: =M25*L25 -> 0 | O25: =L25+N25 -> 2324024 | P25: 0.08 | Q25: =O25*P25 -> 185921.92 | R25: 121 | S25: =G25/R25 -> 0.74214876 | T25: =L25 -> 2324024 | U25: 0 | V25: =T25*U25 -> 0 | W25: 802.2 | X25: =G25-W25 -> -712.4
A26: 8 | C26: Ấm pha trà bằng gốm đất nung không tráng men (Tử Sa) dáng Bát Phương Nung Củi, màu vàng Đoạn Nê, dung tích 270ml, không dùng điện, không hiệu, NSX: Shenzhen Tao Hui Industrial Co., Ltd., Mới 100% | D26: PCE | E26: 10 | F26: 16.74 | G26: =E26*F26 -> 167.4 | I26: 69120000 | J26: =F26*$L$12 -> 433231.2 | K26: 444058 | L26: =G26*$L$12 -> 4332312 | M26: 0 | N26: =M26*L26 -> 0 | O26: =L26+N26 -> 4332312 | P26: 0.08 | Q26: =O26*P26 -> 346584.96 | R26: 122 | S26: =G26/R26 -> 1.3721311 | T26: =L26 -> 4332312 | U26: 0 | V26: =T26*U26 -> 0 | W26: 651.6 | X26: =G26-W26 -> -484.2
A27: 9 | C27: Ấm pha trà bằng gốm đất nung không tráng men (Tử Sa) dáng Thạch Biều, màu xanh Lục Nê, dung tích 260ml, không dùng điện, không hiệu, NSX: Shenzhen Tao Hui Industrial Co., Ltd., Mới 100% | D27: PCE | E27: 5 | F27: 15.69 | G27: =E27*F27 -> 78.45 | I27: 69120000 | J27: =F27*$L$12 -> 406057.2 | K27: 416304 | L27: =G27*$L$12 -> 2030286 | M27: 0 | N27: =M27*L27 -> 0 | O27: =L27+N27 -> 2030286 | P27: 0.08 | Q27: =O27*P27 -> 162422.88 | R27: 123 | S27: =G27/R27 -> 0.63780488 | T27: =L27 -> 2030286 | U27: 0 | V27: =T27*U27 -> 0 | W27: 937.5 | X27: =G27-W27 -> -859.05
A28: 10 | C28: Ấm pha trà bằng gốm đất nung không tráng men (Tử Sa) dáng Vân Lư, màu nâu Thiết Huyết Hồng Sa, dung tích 260ml, không dùng điện, không hiệu, NSX: Shenzhen Tao Hui Industrial Co., Ltd., Mới 100% | D28: PCE | E28: 10 | F28: 17.09 | G28: =E28*F28 -> 170.9 | I28: 69120000 | J28: =F28*$L$12 -> 442289.2 | K28: 453309 | L28: =G28*$L$12 -> 4422892 | M28: 0 | N28: =M28*L28 -> 0 | O28: =L28+N28 -> 4422892 | P28: 0.08 | Q28: =O28*P28 -> 353831.36 | R28: 124 | S28: =G28/R28 -> 1.3782258 | T28: =L28 -> 4422892 | U28: 0 | V28: =T28*U28 -> 0 | W28: 10912 | X28: =G28-W28 -> -10741.1
A29: 11 | C29: Ấm pha trà bằng gốm đất nung không tráng men (Tử Sa) dáng Tứ Phương Liên Hoa dung tích 230ml, không dùng điện, không hiệu, NSX: Shenzhen Tao Hui Industrial Co., Ltd., Mới 100% | D29: PCE | E29: 10 | F29: 14.47 | G29: =E29*F29 -> 144.7 | I29: 69120000 | J29: =F29*$L$12 -> 374483.6 | K29: 383925 | L29: =G29*$L$12 -> 3744836 | M29: 0 | N29: =M29*L29 -> 0 | O29: =L29+N29 -> 3744836 | P29: 0.08 | Q29: =O29*P29 -> 299586.88 | R29: 125 | S29: =G29/R29 -> 1.1576 | T29: =L29 -> 3744836 | U29: 0 | V29: =T29*U29 -> 0 | W29: 3017.5 | X29: =G29-W29 -> -2872.8
A30: 12 | B30: CN090110-1HN | C30: Ấm pha trà bằng gốm đất nung không tráng men (Tử Sa) dáng Long Đán, màu nâu Tử Nê, dung tích 220ml, không dùng điện, không hiệu, NSX: Shenzhen Tao Hui Industrial Co., Ltd., Mới 100% | D30: PCE | E30: 3 | F30: 20.46 | G30: =E30*F30 -> 61.38 | I30: 69120000 | J30: =F30*$L$12 -> 529504.8 | K30: 542800 | L30: =G30*$L$12 -> 1588514.4 | M30: 0 | N30: =M30*L30 -> 0 | O30: =L30+N30 -> 1588514.4 | P30: 0.08 | Q30: =O30*P30 -> 127081.15 | R30: 126 | S30: =G30/R30 -> 0.48714286 | T30: =L30 -> 1588514.4 | U30: 0 | V30: =T30*U30 -> 0 | W30: 300 | X30: =G30-W30 -> -238.62
A31: 13 | C31: Ấm pha trà bằng gốm đất nung không tráng men (Tử Sa) dáng Phan Hồ, màu đỏ Đại Hồng Bào, dung tích 250ml, không dùng điện, không hiệu, NSX: Shenzhen Tao Hui Industrial Co., Ltd., Mới 100% | D31: PCE | E31: 3 | F31: 28.47 | G31: =E31*F31 -> 85.41 | I31: 69120000 | J31: =F31*$L$12 -> 736803.6 | K31: 755200 | L31: =G31*$L$12 -> 2210410.8 | M31: 0 | N31: =M31*L31 -> 0 | O31: =L31+N31 -> 2210410.8 | P31: 0.08 | Q31: =O31*P31 -> 176832.86 | R31: 127 | S31: =G31/R31 -> 0.67251969 | T31: =L31 -> 2210410.8 | U31: 0 | V31: =T31*U31 -> 0 | W31: 448 | X31: =G31-W31 -> -362.59
A32: 14 | C32: Ấm pha trà bằng gốm đất nung không tráng men (Tử Sa) dáng Tây Thi, dung tích 420ml, không dùng điện, không hiệu, NSX: Shenzhen Tao Hui Industrial Co., Ltd., Mới 100% | D32: PCE | E32: 5 | F32: 39.15 | G32: =E32*F32 -> 195.75 | I32: 69120000 | J32: =F32*$L$12 -> 1013202 | K32: 1038400 | L32: =G32*$L$12 -> 5066010 | M32: 0 | N32: =M32*L32 -> 0 | O32: =L32+N32 -> 5066010 | P32: 0.08 | Q32: =O32*P32 -> 405280.8 | R32: 128 | S32: =G32/R32 -> 1.5292969 | T32: =L32 -> 5066010 | U32: 0 | V32: =T32*U32 -> 0 | W32: 240 | X32: =G32-W32 -> -44.25
A33: 15 | C33: Khay để ấm trà (Thuyền Trà) bằng gốm đất nung không tráng men (Tử Sa) đường kính 19.5cm, họa tiết Sơn Cảnh, đóng hộp quà tặng, không hiệu, NSX: Shenzhen Tao Hui Industrial Co., Ltd., Mới 100% | D33: PCE | E33: 5 | F33: 26.69 | G33: =E33*F33 -> 133.45 | I33: 69120000 | J33: =F33*$L$12 -> 690737.2 | K33: 708000 | L33: =G33*$L$12 -> 3453686 | M33: 0 | N33: =M33*L33 -> 0 | O33: =L33+N33 -> 3453686 | P33: 0.08 | Q33: =O33*P33 -> 276294.88 | R33: 129 | S33: =G33/R33 -> 1.0344961 | T33: =L33 -> 3453686 | U33: 0 | V33: =T33*U33 -> 0 | W33: 217.8 | X33: =G33-W33 -> -84.35
A34: 16 | C34: Ang trà ( bát tráng trà) bằng gốm đất nung không tráng men (Tử Sa), màu cam Chu Nê, họa tiết Tâm Kinh đường kính 27.8cm, không hiệu, NSX: Shenzhen Tao Hui Industrial Co., Ltd., Mới 100% | D34: PCE | E34: 5 | F34: 24.02 | G34: =E34*F34 -> 120.1 | I34: 69120000 | J34: =F34*$L$12 -> 621637.6 | K34: 637200 | L34: =G34*$L$12 -> 3108188 | M34: 0 | N34: =M34*L34 -> 0 | O34: =L34+N34 -> 3108188 | P34: 0.08 | Q34: =O34*P34 -> 248655.04 | R34: 130 | S34: =G34/R34 -> 0.92384615 | T34: =L34 -> 3108188 | U34: 0 | V34: =T34*U34 -> 0 | W34: 3016 | X34: =G34-W34 -> -2895.9
A35: 17 | C35: Ấm pha trà bằng gốm đất nung không tráng men (Tử Sa) dáng Thạch Biều Cảnh Chu, màu nâu Tử Nê, dung tích 230ml, không dùng điện, không hiệu, NSX: Shenzhen Tao Hui Industrial Co., Ltd., Mới 100% | D35: PCE | E35: 5 | F35: 53.38 | G35: =E35*F35 -> 266.9 | I35: 69120000 | J35: =F35*$L$12 -> 1381474.4 | K35: 1416000 | L35: =G35*$L$12 -> 6907372 | M35: 0 | N35: =M35*L35 -> 0 | O35: =L35+N35 -> 6907372 | P35: 0.08 | Q35: =O35*P35 -> 552589.76 | R35: 131 | S35: =G35/R35 -> 2.0374046 | T35: =L35 -> 6907372 | U35: 0 | V35: =T35*U35 -> 0 | W35: 590.4 | X35: =G35-W35 -> -323.5
A36: 18 | C36: Ấm pha trà bằng gốm đất nung không tráng men (Tử Sa) dáng Mỹ Nhân Kiên, màu đỏ Đại Hồng Bào, dung tích 190ml, không dùng điện, không hiệu, NSX: Shenzhen Tao Hui Industrial Co., Ltd., Mới 100% | D36: PCE | E36: 5 | F36: 29.89 | G36: =E36*F36 -> 149.45 | I36: 69120000 | J36: =F36*$L$12 -> 773553.2 | K36: 792960 | L36: =G36*$L$12 -> 3867766 | M36: 0 | N36: =M36*L36 -> 0 | O36: =L36+N36 -> 3867766 | P36: 0.08 | Q36: =O36*P36 -> 309421.28 | R36: 132 | S36: =G36/R36 -> 1.132197 | T36: =L36 -> 3867766 | U36: 0 | V36: =T36*U36 -> 0 | W36: 932.8 | X36: =G36-W36 -> -783.35
A37: 19 | C37: Ấm pha trà bằng gốm đất nung không tráng men (Tử Sa) dáng Tây Thi Song Sắc, dung tích 200ml, không dùng điện, không hiệu, NSX: Shenzhen Tao Hui Industrial Co., Ltd., Mới 100% | D37: PCE | E37: 3 | F37: 32.03 | G37: =E37*F37 -> 96.09 | I37: 69120000 | J37: =F37*$L$12 -> 828936.4 | K37: 849600 | L37: =G37*$L$12 -> 2486809.2 | M37: 0 | N37: =M37*L37 -> 0 | O37: =L37+N37 -> 2486809.2 | P37: 0.08 | Q37: =O37*P37 -> 198944.74 | R37: 133 | S37: =G37/R37 -> 0.7224812 | T37: =L37 -> 2486809.2 | U37: 0 | V37: =T37*U37 -> 0 | W37: 401.76 | X37: =G37-W37 -> -305.67
A38: 20 | B38: CN082415-12HN | C38: Công tắc điều khiển dòng chảy, model: HFS-25, dùng cho công nghiệp đóng ngắt dòng điện 5A. KT: (10*7*5)cm+/-10%, đk: ren 1-3/4inch, đ/áp: 220V, hiệu: SUNSES, mới 100% | D38: PCE | E38: 500 | F38: 5.47 | G38: =E38*F38 -> 2735 | I38: 85365096 | J38: =F38*$L$12 -> 141563.6 | K38: 145000 | L38: =G38*$L$12 -> 70781800 | M38: 0 | N38: =M38*L38 -> 0 | O38: =L38+N38 -> 70781800 | P38: 0.08 | Q38: =O38*P38 -> 5662544 | R38: 134 | S38: =G38/R38 -> 20.410448 | T38: =L38 -> 70781800 | U38: 0 | V38: =T38*U38 -> 0 | W38: 272 | X38: =G38-W38 -> 2463
A39: 21 | C39: Công tắc áp suất khí nén KP, bằng nhựa kết hợp đồng, để điều chỉnh áp suất trong hệ thống khí nén, đ/áp: 220V/5A, không hiệu. NSX: Zhejiang Machinery Technology Co., LTD, mới 100% | D39: PCE | E39: 300 | F39: 8.29 | G39: =E39*F39 -> 2487 | I39: 85365096 | J39: =F39*$L$12 -> 214545.2 | K39: 220000 | L39: =G39*$L$12 -> 64363560 | M39: 0 | N39: =M39*L39 -> 0 | O39: =L39+N39 -> 64363560 | P39: 0.08 | Q39: =O39*P39 -> 5149084.8 | R39: 135 | S39: =G39/R39 -> 18.422222 | T39: =L39 -> 64363560 | U39: 0 | V39: =T39*U39 -> 0 | W39: 572.8 | X39: =G39-W39 -> 1914.2
A40: 22 | C40: Đế chia khí dùng cho đường ống khí nén, bằng hợp kim nhôm, loại 3-5 cổng, ren 13mm, áp suất làm việc 1 MPa. KT: (15*5*2)cm+/-10%, không hiệu, nsx: NSX Aikes Pneumatic Components Co., Ltd, mới 100% | D40: PCE | E40: 300 | F40: 4.49 | G40: =E40*F40 -> 1347 | I40: 73269099 | J40: =F40*$L$12 -> 116201.2 | K40: 119000 | L40: =G40*$L$12 -> 34860360 | M40: 0 | N40: =M40*L40 -> 0 | O40: =L40+N40 -> 34860360 | P40: 0.08 | Q40: =O40*P40 -> 2788828.8 | R40: 136 | S40: =G40/R40 -> 9.9044118 | T40: =L40 -> 34860360 | U40: 0 | V40: =T40*U40 -> 0 | W40: 230 | X40: =G40-W40 -> 1117
A41: 23 | B41: CN082915-4HN | C41: Vợt pickleball, model: Bomba X, sử dụng công nghệ ép nóng, lõi eva foam, bề mặt bằng sợi carbon. KT: (40*20*3)cm+/-10%, hiệu: Do-An, mới 100% | D41: PCE | E41: 400 | F41: 9.24 | G41: =E41*F41 -> 3696 | I41: 95069990 | J41: =F41*$L$12 -> 239131.2 | K41: 245000 | L41: =G41*$L$12 -> 95652480 | M41: 0 | N41: =M41*L41 -> 0 | O41: =L41+N41 -> 95652480 | P41: 0.08 | Q41: =O41*P41 -> 7652198.4 | R41: 137 | S41: =G41/R41 -> 26.978102 | T41: =L41 -> 95652480 | U41: 0 | V41: =T41*U41 -> 0 | W41: 67.5 | X41: =G41-W41 -> 3628.5
A42: 24 | B42: CN082916-5HN | C42: Yếm cho thú cưng, chất liệu vải dệt từ sợi tổng hợp. KT: (25*20*2)cm+/-10%, không hiệu. NSX: Ningbo Jia Chong International Trade Co., Ltd.., mới 100% | D42: PCE | E42: 270 | F42: 0.92 | G42: =E42*F42 -> 248.4 | I42: 42010000 | J42: =F42*$L$12 -> 23809.6 | K42: 24371 | L42: =G42*$L$12 -> 6428592 | M42: 0 | N42: =M42*L42 -> 0 | O42: =L42+N42 -> 6428592 | P42: 0.08 | Q42: =O42*P42 -> 514287.36 | R42: 138 | S42: =G42/R42 -> 1.8 | T42: =L42 -> 6428592 | U42: 0 | V42: =T42*U42 -> 0 | W42: 57 | X42: =G42-W42 -> 191.4
...

Sheet INV TIẾNG ANH
A1: PINGXIANG GUIFENG TRADING CO.,LTD
A2: ADD: NO.6 PHASE II PAVEMENT BAIYUN FIELD TIANNAN SECONDARY PINGXIANG CITY GUANGXI CHINA
A3: COMMERCIAL INVOICE | H3: CẤM XÓA
D4: No: | E4: =I4&"GF-TH/26" -> 0902 GF-TH/26 | H4: Số HĐ | I4: ='HỢP ĐỒNG'!$I$1 -> 0902 | J4: =I4&"GF-TH/26" -> 0902 GF-TH/26
D5: Date: | E5: ='HỢP ĐỒNG'!I2+1 -> 46271 | H5: Ngày Hợp đồng | I5: ='HỢP ĐỒNG'!I2 -> 46270
A6: BUYER: TRUONG HAI TRADING AND IMPORT-EXPORT COMPANY LIMITED
A7: Address: No. 12, Secondary Road No. 4, Phu Loc 2 Urban Area, Ky Lua Ward, Lang Son Province, Vietnam.
A9: No | B9: Product name | C9: Unit | D9: Quantity | E9: Unit price (USD) | F9: Total (USD) | G9: HS CODE
A10: ='HỢP ĐỒNG'!A19 -> 1 | B10: ='INVOICE lam CO'!B15 -> Dusting cloth | C10: ='INVOICE lam CO'!D15 -> PCE | D10: ='INVOICE lam CO'!E15 -> 20000 | E10: ='HỢP ĐỒNG'!F19 -> 0.094 | F10: ='HỢP ĐỒNG'!G19 -> 1880 | G10: ='HỢP ĐỒNG'!I19 -> 63071090 | H10: ='HỢP ĐỒNG'!I19 -> 63071090
A11: ='HỢP ĐỒNG'!A20 -> 2 | B11: ='INVOICE lam CO'!B16 -> Tea set | C11: ='INVOICE lam CO'!D16 -> SET | D11: ='INVOICE lam CO'!E16 -> 20 | E11: ='HỢP ĐỒNG'!F20 -> 5.16 | F11: ='HỢP ĐỒNG'!G20 -> 103.2 | G11: ='HỢP ĐỒNG'!I20 -> 69120000 | H11: ='HỢP ĐỒNG'!I20 -> 69120000
A12: ='HỢP ĐỒNG'!A21 -> 3 | B12: ='INVOICE lam CO'!B17 -> Tea set | C12: ='INVOICE lam CO'!D17 -> SET | D12: ='INVOICE lam CO'!E17 -> 20 | E12: ='HỢP ĐỒNG'!F21 -> 4.09 | F12: ='HỢP ĐỒNG'!G21 -> 81.8 | G12: ='HỢP ĐỒNG'!I21 -> 69120000 | H12: ='HỢP ĐỒNG'!I21 -> 69120000
A13: ='HỢP ĐỒNG'!A22 -> 4 | B13: ='INVOICE lam CO'!B18 -> Tea set | C13: ='INVOICE lam CO'!D18 -> SET | D13: ='INVOICE lam CO'!E18 -> 50 | E13: ='HỢP ĐỒNG'!F22 -> 5.69 | F13: ='HỢP ĐỒNG'!G22 -> 284.5 | G13: ='HỢP ĐỒNG'!I22 -> 69120000 | H13: ='HỢP ĐỒNG'!I22 -> 69120000
A14: ='HỢP ĐỒNG'!A23 -> 5 | B14: ='INVOICE lam CO'!B19 -> Teapot | C14: ='INVOICE lam CO'!D19 -> PCE | D14: ='INVOICE lam CO'!E19 -> 10 | E14: ='HỢP ĐỒNG'!F23 -> 13.6 | F14: ='HỢP ĐỒNG'!G23 -> 136 | G14: ='HỢP ĐỒNG'!I23 -> 69120000 | H14: ='HỢP ĐỒNG'!I23 -> 69120000
A15: ='HỢP ĐỒNG'!A24 -> 6 | B15: ='INVOICE lam CO'!B20 -> Teapot | C15: ='INVOICE lam CO'!D20 -> PCE | D15: ='INVOICE lam CO'!E20 -> 15 | E15: ='HỢP ĐỒNG'!F24 -> 10.46 | F15: ='HỢP ĐỒNG'!G24 -> 156.9 | G15: ='HỢP ĐỒNG'!I24 -> 69120000 | H15: ='HỢP ĐỒNG'!I24 -> 69120000
A16: ='HỢP ĐỒNG'!A25 -> 7 | B16: ='INVOICE lam CO'!B21 -> Tea cup | C16: ='INVOICE lam CO'!D21 -> PCE | D16: ='INVOICE lam CO'!E21 -> 20 | E16: ='HỢP ĐỒNG'!F25 -> 4.49 | F16: ='HỢP ĐỒNG'!G25 -> 89.8 | G16: ='HỢP ĐỒNG'!I25 -> 69120000 | H16: ='HỢP ĐỒNG'!I25 -> 69120000
A17: ='HỢP ĐỒNG'!A26 -> 8 | B17: ='INVOICE lam CO'!B22 -> Teapot | C17: ='INVOICE lam CO'!D22 -> PCE | D17: ='INVOICE lam CO'!E22 -> 10 | E17: ='HỢP ĐỒNG'!F26 -> 16.74 | F17: ='HỢP ĐỒNG'!G26 -> 167.4 | G17: ='HỢP ĐỒNG'!I26 -> 69120000 | H17: ='HỢP ĐỒNG'!I26 -> 69120000
A18: ='HỢP ĐỒNG'!A27 -> 9 | B18: ='INVOICE lam CO'!B23 -> Teapot | C18: ='INVOICE lam CO'!D23 -> PCE | D18: ='INVOICE lam CO'!E23 -> 5 | E18: ='HỢP ĐỒNG'!F27 -> 15.69 | F18: ='HỢP ĐỒNG'!G27 -> 78.45 | G18: ='HỢP ĐỒNG'!I27 -> 69120000 | H18: ='HỢP ĐỒNG'!I27 -> 69120000
A19: ='HỢP ĐỒNG'!A28 -> 10 | B19: ='INVOICE lam CO'!B24 -> Teapot | C19: ='INVOICE lam CO'!D24 -> PCE | D19: ='INVOICE lam CO'!E24 -> 10 | E19: ='HỢP ĐỒNG'!F28 -> 17.09 | F19: ='HỢP ĐỒNG'!G28 -> 170.9 | G19: ='HỢP ĐỒNG'!I28 -> 69120000 | H19: ='HỢP ĐỒNG'!I28 -> 69120000
A20: ='HỢP ĐỒNG'!A29 -> 11 | B20: ='INVOICE lam CO'!B25 -> Teapot | C20: ='INVOICE lam CO'!D25 -> PCE | D20: ='INVOICE lam CO'!E25 -> 10 | E20: ='HỢP ĐỒNG'!F29 -> 14.47 | F20: ='HỢP ĐỒNG'!G29 -> 144.7 | G20: ='HỢP ĐỒNG'!I29 -> 69120000 | H20: ='HỢP ĐỒNG'!I29 -> 69120000
A21: ='HỢP ĐỒNG'!A30 -> 12 | B21: ='INVOICE lam CO'!B26 -> Teapot | C21: ='INVOICE lam CO'!D26 -> PCE | D21: ='INVOICE lam CO'!E26 -> 3 | E21: ='HỢP ĐỒNG'!F30 -> 20.46 | F21: ='HỢP ĐỒNG'!G30 -> 61.38 | G21: ='HỢP ĐỒNG'!I30 -> 69120000 | H21: ='HỢP ĐỒNG'!I30 -> 69120000
... A131: ='HỢP ĐỒNG'!A140 -> 122 | B131: ='INVOICE lam CO'!B136 -> Artificial tulip | C131: ='INVOICE lam CO'!D136 -> PCE | D131: ='INVOICE lam CO'!E136 -> 10000 | E131: ='HỢP ĐỒNG'!F140 -> 0.075 | F131: ='HỢP ĐỒNG'!G140 -> 750 | G131: ='HỢP ĐỒNG'!I140 -> 67029090 | H131: ='HỢP ĐỒNG'!I140 -> 67029090
A132: ='HỢP ĐỒNG'!A141 -> 123 | B132: ='INVOICE lam CO'!B137 -> Flower wrapping paper | C132: ='INVOICE lam CO'!D137 -> KGM | D132: ='INVOICE lam CO'!E137 -> 398 | E132: ='HỢP ĐỒNG'!F141 -> 0.8 | F132: ='HỢP ĐỒNG'!G141 -> 318.4
A133: ='HỢP ĐỒNG'!A142 -> 124 | B133: ='INVOICE lam CO'!B138 -> Paint spraying machine | C133: ='INVOICE lam CO'!D138 -> PCE | D133: ='INVOICE lam CO'!E138 -> 2 | E133: ='HỢP ĐỒNG'!F142 -> 1884.87 | F133: ='HỢP ĐỒNG'!G142 -> 3769.74
B134: TOTAL: | F134: =SUM(F10:F133) -> 193171.09
B137: - The above price is understood as the DAF Tan Thanh - Lang Son price - Incoterms 2000
B138: - Payment method: TTR or Border Trade
B139: - Currency: USD or CNY
B140: - Transportation method: Truck

Sheet INVOICE
A1: PINGXIANG GUIFENG TRADING CO.,LTD
A2: ADD: NO.6 PHASE II PAVEMENT BAIYUN FIELD TIANNAN SECONDARY PINGXIANG CITY GUANGXI CHINA
A3: HÓA ĐƠN THƯƠNG MẠI | J3: CẤM XÓA
E4: SỐ: | F4: =K4&"GF-TH/26" -> 0902 GF-TH/26 | I4: Số HĐ | J4: Số HĐ | K4: ='HỢP ĐỒNG'!$I$1 -> 0902 | L4: =K4&"GF-TH/26" -> 0902 GF-TH/26
E5: NGÀY: | F5: ='HỢP ĐỒNG'!I2+1 -> 46271 | I5: Ngày Hợp đồng | J5: Ngày Hợp đồng | K5: ='HỢP ĐỒNG'!I2 -> 46270
A6: NGƯỜI MUA: CÔNG TY TNHH THƯƠNG MẠI VÀ XUẤT NHẬP KHẨU TRƯỜNG HẢI
A7: Địa chỉ: Số 12 Đường Phụ Số 4, Khu đô thị Phú Lộc 2, Phường Kỳ Lừa, Tỉnh Lạng Sơn, Việt Nam
A8: Tài khoản ngân hàng số: 9328666888 – Ngân hàng Thương mại Cổ phần Quân đội - CN Tây Hà Nội
A10: STT | B10: Tên TA | C10: Tên hàng hóa | D10: ĐVT | E10: Số lượng | F10: Đơn giá (USD) | G10: Thành tiền (USD) | H10: HS CODE
A11: ='HỢP ĐỒNG'!A19 -> 1 | B11: ='INVOICE lam CO'!B15 -> Dusting cloth | C11: ='HỢP ĐỒNG'!C19 -> Khăn lau bụi dùng để lau xe hơi, chất liệu vải dệt kim từ sợi polyester, KT:(30*30)cm, không hiệu, NSX: Qingdao Tao Hui Industrial. Mới 100% | D11: ='HỢP ĐỒNG'!D19 -> PCE | E11: ='HỢP ĐỒNG'!E19 -> 20000 | F11: ='HỢP ĐỒNG'!F19 -> 0.094 | G11: ='HỢP ĐỒNG'!G19 -> 1880 | H11: ='HỢP ĐỒNG'!I19 -> 63071090 | I11: ='HỢP ĐỒNG'!I19 -> 63071090
A12: ='HỢP ĐỒNG'!A20 -> 2 | B12: ='INVOICE lam CO'!B16 -> Tea set | C12: ='HỢP ĐỒNG'!C20 -> Bộ ấm chén pha trà bằng gốm đất nung tráng men rạn Nhữ Diêu,gồm ấm trà dung tích 250ml,chén khải 190ml và chén uống trà 50ml, đóng hộp quà tặng, không hiệu. NSX: Shenzhen Tao Hui Industrial. Mới 100% | D12: ='HỢP ĐỒNG'!D20 -> SET | E12: ='HỢP ĐỒNG'!E20 -> 20 | F12: ='HỢP ĐỒNG'!F20 -> 5.16 | G12: ='HỢP ĐỒNG'!G20 -> 103.2 | H12: ='HỢP ĐỒNG'!I20 -> 69120000 | I12: ='HỢP ĐỒNG'!I20 -> 69120000
A13: ='HỢP ĐỒNG'!A21 -> 3 | B13: ='INVOICE lam CO'!B17 -> Tea set | C13: ='HỢP ĐỒNG'!C21 -> Bộ ấm chén pha trà du lịch bằng gốm đất nung tráng men trắng, dáng Tây Thi họa tiết Núi Non, gồm ấm trà dung tích 270ml, tống trà 150ml, chén trà 50ml,đóng hộp quà tặng, không hiệu, Mới 100% | D13: ='HỢP ĐỒNG'!D21 -> SET | E13: ='HỢP ĐỒNG'!E21 -> 20 | F13: ='HỢP ĐỒNG'!F21 -> 4.09 | G13: ='HỢP ĐỒNG'!G21 -> 81.8 | H13: ='HỢP ĐỒNG'!I21 -> 69120000 | I13: ='HỢP ĐỒNG'!I21 -> 69120000
A14: ='HỢP ĐỒNG'!A22 -> 4 | B14: ='INVOICE lam CO'!B18 -> Tea set | C14: ='HỢP ĐỒNG'!C22 -> Bộ ấm chén trà bằng gốm đất nung, kiểu dáng Nhật gồm 1 ấm 200ml và 4 chén 60ml kèm hộp quà tặng, không hiệu, NSX: Shenzhen Tao Hui Industrial Co., Ltd., Mới 100% | D14: ='HỢP ĐỒNG'!D22 -> SET | E14: ='HỢP ĐỒNG'!E22 -> 50 | F14: ='HỢP ĐỒNG'!F22 -> 5.69 | G14: ='HỢP ĐỒNG'!G22 -> 284.5 | H14: ='HỢP ĐỒNG'!I22 -> 69120000 | I14: ='HỢP ĐỒNG'!I22 -> 69120000
A15: ='HỢP ĐỒNG'!A23 -> 5 | B15: ='INVOICE lam CO'!B19 -> Teapot | C15: ='HỢP ĐỒNG'!C23 -> Ấm pha trà bằng gốm đất nung không tráng men (Tử Sa) dáng Hán Ngõa, màu xanh Lục Nê, dung tích 240ml, không dùng điện, không hiệu, NSX: Shenzhen Tao Hui Industrial Co., Ltd., Mới 100% | D15: ='HỢP ĐỒNG'!D23 -> PCE | E15: ='HỢP ĐỒNG'!E23 -> 10 | F15: ='HỢP ĐỒNG'!F23 -> 13.6 | G15: ='HỢP ĐỒNG'!G23 -> 136 | H15: ='HỢP ĐỒNG'!I23 -> 69120000 | I15: ='HỢP ĐỒNG'!I23 -> 69120000
A16: ='HỢP ĐỒNG'!A24 -> 6 | B16: ='INVOICE lam CO'!B20 -> Teapot | C16: ='HỢP ĐỒNG'!C24 -> Ấm pha trà bằng gốm đất nung không tráng men (Tử Sa) dáng Tây Thi, màu đỏ Đại Hồng Bào, dung tích 240ml, không dùng điện, không hiệu, NSX: Shenzhen Tao Hui Industrial Co., Ltd., Mới 100% | D16: ='HỢP ĐỒNG'!D24 -> PCE | E16: ='HỢP ĐỒNG'!E24 -> 15 | F16: ='HỢP ĐỒNG'!F24 -> 10.46 | G16: ='HỢP ĐỒNG'!G24 -> 156.9 | H16: ='HỢP ĐỒNG'!I24 -> 69120000 | I16: ='HỢP ĐỒNG'!I24 -> 69120000
A17: ='HỢP ĐỒNG'!A25 -> 7 | B17: ='INVOICE lam CO'!B21 -> Tea cup | C17: ='HỢP ĐỒNG'!C25 -> Cốc uống trà bằng gốm đất nung không tráng men (Tử Sa) họa tiết Thiên Hương, dung tích 180ml, không hiệu, NSX: Shenzhen Tao Hui Industrial Co., Ltd., Mới 100% | D17: ='HỢP ĐỒNG'!D25 -> PCE | E17: ='HỢP ĐỒNG'!E25 -> 20 | F17: ='HỢP ĐỒNG'!F25 -> 4.49 | G17: ='HỢP ĐỒNG'!G25 -> 89.8 | H17: ='HỢP ĐỒNG'!I25 -> 69120000 | I17: ='HỢP ĐỒNG'!I25 -> 69120000
A18: ='HỢP ĐỒNG'!A26 -> 8 | B18: ='INVOICE lam CO'!B22 -> Teapot | C18: ='HỢP ĐỒNG'!C26 -> Ấm pha trà bằng gốm đất nung không tráng men (Tử Sa) dáng Bát Phương Nung Củi, màu vàng Đoạn Nê, dung tích 270ml, không dùng điện, không hiệu, NSX: Shenzhen Tao Hui Industrial Co., Ltd., Mới 100% | D18: ='HỢP ĐỒNG'!D26 -> PCE | E18: ='HỢP ĐỒNG'!E26 -> 10 | F18: ='HỢP ĐỒNG'!F26 -> 16.74 | G18: ='HỢP ĐỒNG'!G26 -> 167.4 | H18: ='HỢP ĐỒNG'!I26 -> 69120000 | I18: ='HỢP ĐỒNG'!I26 -> 69120000
A19: ='HỢP ĐỒNG'!A27 -> 9 | B19: ='INVOICE lam CO'!B23 -> Teapot | C19: ='HỢP ĐỒNG'!C27 -> Ấm pha trà bằng gốm đất nung không tráng men (Tử Sa) dáng Thạch Biều, màu xanh Lục Nê, dung tích 260ml, không dùng điện, không hiệu, NSX: Shenzhen Tao Hui Industrial Co., Ltd., Mới 100% | D19: ='HỢP ĐỒNG'!D27 -> PCE | E19: ='HỢP ĐỒNG'!E27 -> 5 | F19: ='HỢP ĐỒNG'!F27 -> 15.69 | G19: ='HỢP ĐỒNG'!G27 -> 78.45 | H19: ='HỢP ĐỒNG'!I27 -> 69120000 | I19: ='HỢP ĐỒNG'!I27 -> 69120000
A20: ='HỢP ĐỒNG'!A28 -> 10 | B20: ='INVOICE lam CO'!B24 -> Teapot | C20: ='HỢP ĐỒNG'!C28 -> Ấm pha trà bằng gốm đất nung không tráng men (Tử Sa) dáng Vân Lư, màu nâu Thiết Huyết Hồng Sa, dung tích 260ml, không dùng điện, không hiệu, NSX: Shenzhen Tao Hui Industrial Co., Ltd., Mới 100% | D20: ='HỢP ĐỒNG'!D28 -> PCE | E20: ='HỢP ĐỒNG'!E28 -> 10 | F20: ='HỢP ĐỒNG'!F28 -> 17.09 | G20: ='HỢP ĐỒNG'!G28 -> 170.9 | H20: ='HỢP ĐỒNG'!I28 -> 69120000 | I20: ='HỢP ĐỒNG'!I28 -> 69120000
A21: ='HỢP ĐỒNG'!A29 -> 11 | B21: ='INVOICE lam CO'!B25 -> Teapot | C21: ='HỢP ĐỒNG'!C29 -> Ấm pha trà bằng gốm đất nung không tráng men (Tử Sa) dáng Tứ Phương Liên Hoa dung tích 230ml, không dùng điện, không hiệu, NSX: Shenzhen Tao Hui Industrial Co., Ltd., Mới 100% | D21: ='HỢP ĐỒNG'!D29 -> PCE | E21: ='HỢP ĐỒNG'!E29 -> 10 | F21: ='HỢP ĐỒNG'!F29 -> 14.47 | G21: ='HỢP ĐỒNG'!G29 -> 144.7 | H21: ='HỢP ĐỒNG'!I29 -> 69120000 | I21: ='HỢP ĐỒNG'!I29 -> 69120000
A22: ='HỢP ĐỒNG'!A30 -> 12 | B22: ='INVOICE lam CO'!B26 -> Teapot | C22: ='HỢP ĐỒNG'!C30 -> Ấm pha trà bằng gốm đất nung không tráng men (Tử Sa) dáng Long Đán, màu nâu Tử Nê, dung tích 220ml, không dùng điện, không hiệu, NSX: Shenzhen Tao Hui Industrial Co., Ltd., Mới 100% | D22: ='HỢP ĐỒNG'!D30 -> PCE | E22: ='HỢP ĐỒNG'!E30 -> 3 | F22: ='HỢP ĐỒNG'!F30 -> 20.46 | G22: ='HỢP ĐỒNG'!G30 -> 61.38 | H22: ='HỢP ĐỒNG'!I30 -> 69120000 | I22: ='HỢP ĐỒNG'!I30 -> 69120000
... A132: ='HỢP ĐỒNG'!A140 -> 122 | B132: ='INVOICE lam CO'!B136 -> Artificial tulip | C132: ='HỢP ĐỒNG'!C140 -> Bông hoa tuylip nhân tạo, chất liệu nhựa PVC, lõi bằng thép, đã định hình hoàn chỉnh, dùng để trang trí. KT: (35*4)cm+/-10%, không hiệu. NSX: Yuchen Artificial Flower Strength Supplier, mới 100% | D132: ='HỢP ĐỒNG'!D140 -> PCE | E132: ='HỢP ĐỒNG'!E140 -> 10000 | F132: ='HỢP ĐỒNG'!F140 -> 0.075 | G132: ='HỢP ĐỒNG'!G140 -> 750 | H132: ='HỢP ĐỒNG'!I140 -> 67029090 | I132: ='HỢP ĐỒNG'!I140 -> 67029090
B133: ='INVOICE lam CO'!B137 -> Flower wrapping paper | C133: ='HỢP ĐỒNG'!C141 -> Giấy gói hoa dạng giấy nhún, được làm từ bột gỗ xenlulo, đã nhuộm màu bề mặt, dạng tấm, KT: (50*230)cm+/-10%, không hiệu. Nsx: Jiangxi Yuanna Packaging Material Co., Ltd. Mới 100% | D133: ='HỢP ĐỒNG'!D141 -> KGM | E133: ='HỢP ĐỒNG'!E141 -> 398 | F133: ='HỢP ĐỒNG'!F141 -> 0.8 | G133: ='HỢP ĐỒNG'!G141 -> 318.4 | I133: ='HỢP ĐỒNG'!I141 -> 48119093
B134: ='INVOICE lam CO'!B138 -> Paint spraying machine | C134: ='HỢP ĐỒNG'!C142 -> Máy phun sơn tĩnh điện dùng để phun sơn hoàn thiện bề mặt các sản phẩm bằng kim loại,kèm khung đỡ có bánh xe.Model:FlexiSpray F1,điện áp:AC100-240,CS: 50W. NSX: Foshan Debelle Technology,mới 100% | D134: ='HỢP ĐỒNG'!D142 -> PCE | E134: ='HỢP ĐỒNG'!E142 -> 2 | F134: ='HỢP ĐỒNG'!F142 -> 1884.87 | G134: ='HỢP ĐỒNG'!G142 -> 3769.74 | I134: ='HỢP ĐỒNG'!I142 -> 84242029
C135: Tổng cộng: | G135: =SUM(G11:G134) -> 193171.09
C138: - Giá trên được hiểu là giá DAF Tân Thanh - Lạng Sơn - Incoterms 2000
C139: - Phương thức thanh toán: TTR hoặc Biên mậu
C140: - Đồng tiền thanh toán: USD hoặc CNY
C141: - Phương thức vận chuyển: Ô tô tải

Sheet PACKINGLIST
A1: =INVOICE!A1 -> PINGXIANG GUIFENG TRADING CO.,LTD
A2: =INVOICE!A2 -> ADD: NO.6 PHASE II PAVEMENT BAIYUN FIELD TIANNAN SECONDARY PINGXIANG CITY GUANGXI CHINA
A4: PHIẾU ĐÓNG GÓI
B5: Hóa đơn số: | C5: =INVOICE!F4 -> 0902 GF-TH/26 | F5: ="Ngày "&DAY(INVOICE!F5)&"/"&MONTH(INVOICE!F5)&"/"&YEAR(INVOICE!F5) -> Ngày 6/9/2026
B6: Hợp đồng số: | C6: =C5 -> 0902 GF-TH/26 | F6: ="Ngày "&DAY('HỢP ĐỒNG'!I2)&"/"&MONTH('HỢP ĐỒNG'!I2)&"/"&YEAR('HỢP ĐỒNG'!I2) -> Ngày 5/9/2026
A8: =INVOICE!A6 -> NGƯỜI MUA: CÔNG TY TNHH THƯƠNG MẠI VÀ XUẤT NHẬP KHẨU TRƯỜNG HẢI
A9: =INVOICE!A7 -> Địa chỉ: Số 12 Đường Phụ Số 4, Khu đô thị Phú Lộc 2, Phường Kỳ Lừa, Tỉnh Lạng Sơn, Việt Nam
A10: =INVOICE!A8 -> Tài khoản ngân hàng số: 9328666888 – Ngân hàng Thương mại Cổ phần Quân đội - CN Tây Hà Nội
A12: STT | B12: Chi tiết tên hàng | C12: Đvt | D12: Số lượng | E12: Quy cách đóng gói | F12: Số kiện | G12: Trọng lượng hàng | H12: Trọng lượng cả bì
A13: ='HỢP ĐỒNG'!A19 -> 1 | B13: ='HỢP ĐỒNG'!C19 -> Khăn lau bụi dùng để lau xe hơi, chất liệu vải dệt kim từ sợi polyester, KT:(30*30)cm, không hiệu, NSX: Qingdao Tao Hui Industrial. Mới 100% | C13: ='HỢP ĐỒNG'!D19 -> PCE | D13: ='HỢP ĐỒNG'!E19 -> 20000 | E13: =IF(C13="Kg",IF(I13<D13,I13&" "&C13&" "&"/ Kiện",I13&" "&C13&" "&"/ "&F13&" Kiện"),IF(AND(D13=I13),I13&" "&C13&" "&"/ "&F13&" Kiện",I13&" "&C13&" "&"/ Kiện")) -> PCE / Kiện | F13: 10 | G13: 280 | H13: 300
A14: ='HỢP ĐỒNG'!A20 -> 2 | B14: ='HỢP ĐỒNG'!C20 -> Bộ ấm chén pha trà bằng gốm đất nung tráng men rạn Nhữ Diêu,gồm ấm trà dung tích 250ml,chén khải 190ml và chén uống trà 50ml, đóng hộp quà tặng, không hiệu. NSX: Shenzhen Tao Hui Industrial. Mới 100% | C14: ='HỢP ĐỒNG'!D20 -> SET | D14: ='HỢP ĐỒNG'!E20 -> 20 | F14: 1 | G14: 54 | H14: 56
A15: ='HỢP ĐỒNG'!A21 -> 3 | B15: ='HỢP ĐỒNG'!C21 -> Bộ ấm chén pha trà du lịch bằng gốm đất nung tráng men trắng, dáng Tây Thi họa tiết Núi Non, gồm ấm trà dung tích 270ml, tống trà 150ml, chén trà 50ml,đóng hộp quà tặng, không hiệu, Mới 100% | C15: ='HỢP ĐỒNG'!D21 -> SET | D15: ='HỢP ĐỒNG'!E21 -> 20
A16: ='HỢP ĐỒNG'!A22 -> 4 | B16: ='HỢP ĐỒNG'!C22 -> Bộ ấm chén trà bằng gốm đất nung, kiểu dáng Nhật gồm 1 ấm 200ml và 4 chén 60ml kèm hộp quà tặng, không hiệu, NSX: Shenzhen Tao Hui Industrial Co., Ltd., Mới 100% | C16: ='HỢP ĐỒNG'!D22 -> SET | D16: ='HỢP ĐỒNG'!E22 -> 50
A17: ='HỢP ĐỒNG'!A23 -> 5 | B17: ='HỢP ĐỒNG'!C23 -> Ấm pha trà bằng gốm đất nung không tráng men (Tử Sa) dáng Hán Ngõa, màu xanh Lục Nê, dung tích 240ml, không dùng điện, không hiệu, NSX: Shenzhen Tao Hui Industrial Co., Ltd., Mới 100% | C17: ='HỢP ĐỒNG'!D23 -> PCE | D17: ='HỢP ĐỒNG'!E23 -> 10 | F17: 1 | G17: 47 | H17: 49
A18: ='HỢP ĐỒNG'!A24 -> 6 | B18: ='HỢP ĐỒNG'!C24 -> Ấm pha trà bằng gốm đất nung không tráng men (Tử Sa) dáng Tây Thi, màu đỏ Đại Hồng Bào, dung tích 240ml, không dùng điện, không hiệu, NSX: Shenzhen Tao Hui Industrial Co., Ltd., Mới 100% | C18: ='HỢP ĐỒNG'!D24 -> PCE | D18: ='HỢP ĐỒNG'!E24 -> 15
A19: ='HỢP ĐỒNG'!A25 -> 7 | B19: ='HỢP ĐỒNG'!C25 -> Cốc uống trà bằng gốm đất nung không tráng men (Tử Sa) họa tiết Thiên Hương, dung tích 180ml, không hiệu, NSX: Shenzhen Tao Hui Industrial Co., Ltd., Mới 100% | C19: ='HỢP ĐỒNG'!D25 -> PCE | D19: ='HỢP ĐỒNG'!E25 -> 20
A20: ='HỢP ĐỒNG'!A26 -> 8 | B20: ='HỢP ĐỒNG'!C26 -> Ấm pha trà bằng gốm đất nung không tráng men (Tử Sa) dáng Bát Phương Nung Củi, màu vàng Đoạn Nê, dung tích 270ml, không dùng điện, không hiệu, NSX: Shenzhen Tao Hui Industrial Co., Ltd., Mới 100% | C20: ='HỢP ĐỒNG'!D26 -> PCE | D20: ='HỢP ĐỒNG'!E26 -> 10
A21: ='HỢP ĐỒNG'!A27 -> 9 | B21: ='HỢP ĐỒNG'!C27 -> Ấm pha trà bằng gốm đất nung không tráng men (Tử Sa) dáng Thạch Biều, màu xanh Lục Nê, dung tích 260ml, không dùng điện, không hiệu, NSX: Shenzhen Tao Hui Industrial Co., Ltd., Mới 100% | C21: ='HỢP ĐỒNG'!D27 -> PCE | D21: ='HỢP ĐỒNG'!E27 -> 5
A22: ='HỢP ĐỒNG'!A28 -> 10 | B22: ='HỢP ĐỒNG'!C28 -> Ấm pha trà bằng gốm đất nung không tráng men (Tử Sa) dáng Vân Lư, màu nâu Thiết Huyết Hồng Sa, dung tích 260ml, không dùng điện, không hiệu, NSX: Shenzhen Tao Hui Industrial Co., Ltd., Mới 100% | C22: ='HỢP ĐỒNG'!D28 -> PCE | D22: ='HỢP ĐỒNG'!E28 -> 10
A23: ='HỢP ĐỒNG'!A29 -> 11 | B23: ='HỢP ĐỒNG'!C29 -> Ấm pha trà bằng gốm đất nung không tráng men (Tử Sa) dáng Tứ Phương Liên Hoa dung tích 230ml, không dùng điện, không hiệu, NSX: Shenzhen Tao Hui Industrial Co., Ltd., Mới 100% | C23: ='HỢP ĐỒNG'!D29 -> PCE | D23: ='HỢP ĐỒNG'!E29 -> 10
A24: ='HỢP ĐỒNG'!A30 -> 12 | B24: ='HỢP ĐỒNG'!C30 -> Ấm pha trà bằng gốm đất nung không tráng men (Tử Sa) dáng Long Đán, màu nâu Tử Nê, dung tích 220ml, không dùng điện, không hiệu, NSX: Shenzhen Tao Hui Industrial Co., Ltd., Mới 100% | C24: ='HỢP ĐỒNG'!D30 -> PCE | D24: ='HỢP ĐỒNG'!E30 -> 3 | F24: 1 | G24: 45 | H24: 47
A25: ='HỢP ĐỒNG'!A31 -> 13 | B25: ='HỢP ĐỒNG'!C31 -> Ấm pha trà bằng gốm đất nung không tráng men (Tử Sa) dáng Phan Hồ, màu đỏ Đại Hồng Bào, dung tích 250ml, không dùng điện, không hiệu, NSX: Shenzhen Tao Hui Industrial Co., Ltd., Mới 100% | C25: ='HỢP ĐỒNG'!D31 -> PCE | D25: ='HỢP ĐỒNG'!E31 -> 3
A26: ='HỢP ĐỒNG'!A32 -> 14 | B26: ='HỢP ĐỒNG'!C32 -> Ấm pha trà bằng gốm đất nung không tráng men (Tử Sa) dáng Tây Thi, dung tích 420ml, không dùng điện, không hiệu, NSX: Shenzhen Tao Hui Industrial Co., Ltd., Mới 100% | C26: ='HỢP ĐỒNG'!D32 -> PCE | D26: ='HỢP ĐỒNG'!E32 -> 5
A27: ='HỢP ĐỒNG'!A33 -> 15 | B27: ='HỢP ĐỒNG'!C33 -> Khay để ấm trà (Thuyền Trà) bằng gốm đất nung không tráng men (Tử Sa) đường kính 19.5cm, họa tiết Sơn Cảnh, đóng hộp quà tặng, không hiệu, NSX: Shenzhen Tao Hui Industrial Co., Ltd., Mới 100% | C27: ='HỢP ĐỒNG'!D33 -> PCE | D27: ='HỢP ĐỒNG'!E33 -> 5
A28: ='HỢP ĐỒNG'!A34 -> 16 | B28: ='HỢP ĐỒNG'!C34 -> Ang trà ( bát tráng trà) bằng gốm đất nung không tráng men (Tử Sa), màu cam Chu Nê, họa tiết Tâm Kinh đường kính 27.8cm, không hiệu, NSX: Shenzhen Tao Hui Industrial Co., Ltd., Mới 100% | C28: ='HỢP ĐỒNG'!D34 -> PCE | D28: ='HỢP ĐỒNG'!E34 -> 5
A29: ='HỢP ĐỒNG'!A35 -> 17 | B29: ='HỢP ĐỒNG'!C35 -> Ấm pha trà bằng gốm đất nung không tráng men (Tử Sa) dáng Thạch Biều Cảnh Chu, màu nâu Tử Nê, dung tích 230ml, không dùng điện, không hiệu, NSX: Shenzhen Tao Hui Industrial Co., Ltd., Mới 100% | C29: ='HỢP ĐỒNG'!D35 -> PCE | D29: ='HỢP ĐỒNG'!E35 -> 5
A30: ='HỢP ĐỒNG'!A36 -> 18 | B30: ='HỢP ĐỒNG'!C36 -> Ấm pha trà bằng gốm đất nung không tráng men (Tử Sa) dáng Mỹ Nhân Kiên, màu đỏ Đại Hồng Bào, dung tích 190ml, không dùng điện, không hiệu, NSX: Shenzhen Tao Hui Industrial Co., Ltd., Mới 100% | C30: ='HỢP ĐỒNG'!D36 -> PCE | D30: ='HỢP ĐỒNG'!E36 -> 5
A31: ='HỢP ĐỒNG'!A37 -> 19 | B31: ='HỢP ĐỒNG'!C37 -> Ấm pha trà bằng gốm đất nung không tráng men (Tử Sa) dáng Tây Thi Song Sắc, dung tích 200ml, không dùng điện, không hiệu, NSX: Shenzhen Tao Hui Industrial Co., Ltd., Mới 100% | C31: ='HỢP ĐỒNG'!D37 -> PCE | D31: ='HỢP ĐỒNG'!E37 -> 3
A32: ='HỢP ĐỒNG'!A38 -> 20 | B32: ='HỢP ĐỒNG'!C38 -> Công tắc điều khiển dòng chảy, model: HFS-25, dùng cho công nghiệp đóng ngắt dòng điện 5A. KT: (10*7*5)cm+/-10%, đk: ren 1-3/4inch, đ/áp: 220V, hiệu: SUNSES, mới 100% | C32: ='HỢP ĐỒNG'!D38 -> PCE | D32: ='HỢP ĐỒNG'!E38 -> 500 | F32: 12 | G32: 222 | H32: 246
A33: ='HỢP ĐỒNG'!A39 -> 21 | B33: ='HỢP ĐỒNG'!C39 -> Công tắc áp suất khí nén KP, bằng nhựa kết hợp đồng, để điều chỉnh áp suất trong hệ thống khí nén, đ/áp: 220V/5A, không hiệu. NSX: Zhejiang Machinery Technology Co., LTD, mới 100% | C33: ='HỢP ĐỒNG'!D39 -> PCE | D33: ='HỢP ĐỒNG'!E39 -> 300
A34: ='HỢP ĐỒNG'!A40 -> 22 | B34: ='HỢP ĐỒNG'!C40 -> Đế chia khí dùng cho đường ống khí nén, bằng hợp kim nhôm, loại 3-5 cổng, ren 13mm, áp suất làm việc 1 MPa. KT: (15*5*2)cm+/-10%, không hiệu, nsx: NSX Aikes Pneumatic Components Co., Ltd, mới 100% | C34: ='HỢP ĐỒNG'!D40 -> PCE | D34: ='HỢP ĐỒNG'!E40 -> 300
A35: ='HỢP ĐỒNG'!A41 -> 23 | B35: ='HỢP ĐỒNG'!C41 -> Vợt pickleball, model: Bomba X, sử dụng công nghệ ép nóng, lõi eva foam, bề mặt bằng sợi carbon. KT: (40*20*3)cm+/-10%, hiệu: Do-An, mới 100% | C35: ='HỢP ĐỒNG'!D41 -> PCE | D35: ='HỢP ĐỒNG'!E41 -> 400 | F35: 4 | G35: 50 | H35: 58
A36: ='HỢP ĐỒNG'!A42 -> 24 | B36: ='HỢP ĐỒNG'!C42 -> Yếm cho thú cưng, chất liệu vải dệt từ sợi tổng hợp. KT: (25*20*2)cm+/-10%, không hiệu. NSX: Ningbo Jia Chong International Trade Co., Ltd.., mới 100% | C36: ='HỢP ĐỒNG'!D42 -> PCE | D36: ='HỢP ĐỒNG'!E42 -> 270 | F36: 5 | G36: 112 | H36: 122
A37: ='HỢP ĐỒNG'!A43 -> 25 | B37: ='HỢP ĐỒNG'!C43 -> Dây dắt thú cưng, chất liệu vải dù. KT: 1.2cm*1.5m+/-10%, không hiệu. NSX: Ningbo Jia Chong International Trade Co., Ltd.., mới 100% | C37: ='HỢP ĐỒNG'!D43 -> PCE | D37: ='HỢP ĐỒNG'!E43 -> 400
A38: ='HỢP ĐỒNG'!A44 -> 26 | B38: ='HỢP ĐỒNG'!C44 -> Thanh giá treo của vòi hoa sen cây (gồm 2 thanh), chất liệu thép không gỉ, chống bám bẩn. KT: (1280*370)mm+/-10%, không hiệu,nsx: Jiangyin Yonghao Machinery Co., Ltd. Mới 100% | C38: ='HỢP ĐỒNG'!D44 -> SET | D38: ='HỢP ĐỒNG'!E44 -> 1200 | F38: 50 | G38: 960 | H38: 1061
A39: ='HỢP ĐỒNG'!A45 -> 27 | B39: ='HỢP ĐỒNG'!C45 -> Khay chữ nhật, kí hiệu: SL-170, dùng để trang trí, trưng bày trong khách sạn, chất liệu nhựa giả gỗ. KT: (29.7*21.5*6)cm+/-10%, không hiệu. Nsx: Shandong Machinery Co., Ltd. Mới 100% | C39: ='HỢP ĐỒNG'!D45 -> PCE | D39: ='HỢP ĐỒNG'!E45 -> 48 | F39: 12 | G39: 178 | H39: 202
A40: ='HỢP ĐỒNG'!A46 -> 28 | B40: ='HỢP ĐỒNG'!C46 -> Khay đựng đũa đặt trên bàn ăn dùng trong nhà bếp, không dùng đựng thực phẩm,chất liệu bằng nhựa ABS, kí hiệu: C-1222. KT: (27.3*10.5*6.5)cm+-10%, không hiệu. Nsx: Shandong Machinery Co., Ltd. Mới 100% | C40: ='HỢP ĐỒNG'!D46 -> PCE | D40: ='HỢP ĐỒNG'!E46 -> 150
A41: ='HỢP ĐỒNG'!A47 -> 29 | B41: ='HỢP ĐỒNG'!C47 -> Khay đựng đũa đặt trên bàn ăn dùng trong nhà bếp, không dùng đựng thực phẩm, chất liệu bằng nhựa ABS, kí hiệu: C-1223. KT: (26.5*8.7*5)cm+-10%, không hiệu. Nsx: Shandong Machinery Co., Ltd. Mới 100% | C41: ='HỢP ĐỒNG'!D47 -> PCE | D41: ='HỢP ĐỒNG'!E47 -> 150
A42: ='HỢP ĐỒNG'!A48 -> 30 | B42: ='HỢP ĐỒNG'!C48 -> Nồi lẩu sần 2 ngăn NLS2N32B, dùng trong nhà bếp, không dùng điện, chất liệu inox. ĐK: 32cm+/-10%, không hiệu, nsx: Jiangmen Jida Stainless Steel Products Co., Ltd.. Mới 100% | C42: ='HỢP ĐỒNG'!D48 -> PCE | D42: ='HỢP ĐỒNG'!E48 -> 200 | F42: 14 | G42: 297 | H42: 325
A43: ='HỢP ĐỒNG'!A49 -> 31 | B43: ='HỢP ĐỒNG'!C49 -> Nồi lẩu inox NLS30B, dùng trong nhà bếp, không dùng điện. ĐK: 28cm+/-10%, không hiệu, nsx: Jiangmen Jida Stainless Steel Products Co., Ltd.. Mới 100% | C43: ='HỢP ĐỒNG'!D49 -> PCE | D43: ='HỢP ĐỒNG'!E49 -> 26
...

Sheet nhập máy
A1: STT | B1: Mã hàng | C1: Tên hàng (mô tả chi tiết) | D1: Mã HS | E1: Xuất xứ | F1: S. Lượng | G1: Đơn vị tính | H1: S Lượng 2 | I1: ĐVT 2 | J1: Đơn giá hóa đơn | K1: Trị giá hóa đơn | L1: Mã tiền Trị giá tính thuế | M1: Mã biểu thuế NK | N1: TS NK(%) | O1: Mã áp dụng mức thuế tuyệt đối | P1: (2) Số mục khai khoản điều chỉnh | Q1: (3) Số mục khai khoản điều chỉnh | R1: (4) Số mục khai khoản điều chỉnh | S1: Số đăng ký danh mục miễn thuế NK | T1: Số dòng tương ứng trong danh mục | U1: Mã miễn/ giảm/ không chịu thuế nhập khẩu | V1: Thuế suất TTĐB(%) | W1: Tiền thuế TTĐB | X1: Mã miễn giảm thuế TTĐB | Z1: Thuế suất VAT
A2: ='HỢP ĐỒNG'!A19 -> 1 | C2: ='HỢP ĐỒNG'!C19 -> Khăn lau bụi dùng để lau xe hơi, chất liệu vải dệt kim từ sợi polyester, KT:(30*30)cm, không hiệu, NSX: Qingdao Tao Hui Industrial. Mới 100% | D2: ='HỢP ĐỒNG'!I19 -> 63071090 | E2: CN | F2: ='HỢP ĐỒNG'!E19 -> 20000 | G2: ='INVOICE lam CO'!D15 -> PCE | H2: 280 | I2: KGM | J2: ='HỢP ĐỒNG'!F19 -> 0.094 | M2: B05 | Y2: =IF(Z2=8%,"VB245",IF(Z2=10%,"VB901",IF(Z2=5%,"VB185",""))) -> VB245 | Z2: ='HỢP ĐỒNG'!P19 -> 0.08
A3: ='HỢP ĐỒNG'!A20 -> 2 | C3: ='HỢP ĐỒNG'!C20 -> Bộ ấm chén pha trà bằng gốm đất nung tráng men rạn Nhữ Diêu,gồm ấm trà dung tích 250ml,chén khải 190ml và chén uống trà 50ml, đóng hộp quà tặng, không hiệu. NSX: Shenzhen Tao Hui Industrial. Mới 100% | D3: ='HỢP ĐỒNG'!I20 -> 69120000 | E3: CN | F3: ='HỢP ĐỒNG'!E20 -> 20 | G3: ='INVOICE lam CO'!D16 -> SET | H3: 20 | I3: SET | J3: ='HỢP ĐỒNG'!F20 -> 5.16 | M3: B05 | Y3: =IF(Z3=8%,"VB245",IF(Z3=10%,"VB901",IF(Z3=5%,"VB185",""))) -> VB245 | Z3: ='HỢP ĐỒNG'!P20 -> 0.08
A4: ='HỢP ĐỒNG'!A21 -> 3 | C4: ='HỢP ĐỒNG'!C21 -> Bộ ấm chén pha trà du lịch bằng gốm đất nung tráng men trắng, dáng Tây Thi họa tiết Núi Non, gồm ấm trà dung tích 270ml, tống trà 150ml, chén trà 50ml,đóng hộp quà tặng, không hiệu, Mới 100% | D4: ='HỢP ĐỒNG'!I21 -> 69120000 | E4: CN | F4: ='HỢP ĐỒNG'!E21 -> 20 | G4: ='INVOICE lam CO'!D17 -> SET | H4: 20 | I4: SET | J4: ='HỢP ĐỒNG'!F21 -> 4.09 | M4: B05 | Y4: =IF(Z4=8%,"VB245",IF(Z4=10%,"VB901",IF(Z4=5%,"VB185",""))) -> VB245 | Z4: ='HỢP ĐỒNG'!P21 -> 0.08
A5: ='HỢP ĐỒNG'!A22 -> 4 | C5: ='HỢP ĐỒNG'!C22 -> Bộ ấm chén trà bằng gốm đất nung, kiểu dáng Nhật gồm 1 ấm 200ml và 4 chén 60ml kèm hộp quà tặng, không hiệu, NSX: Shenzhen Tao Hui Industrial Co., Ltd., Mới 100% | D5: ='HỢP ĐỒNG'!I22 -> 69120000 | E5: CN | F5: ='HỢP ĐỒNG'!E22 -> 50 | G5: ='INVOICE lam CO'!D18 -> SET | H5: 50 | I5: SET | J5: ='HỢP ĐỒNG'!F22 -> 5.69 | M5: B05 | Y5: =IF(Z5=8%,"VB245",IF(Z5=10%,"VB901",IF(Z5=5%,"VB185",""))) -> VB245 | Z5: ='HỢP ĐỒNG'!P22 -> 0.08
A6: ='HỢP ĐỒNG'!A23 -> 5 | C6: ='HỢP ĐỒNG'!C23 -> Ấm pha trà bằng gốm đất nung không tráng men (Tử Sa) dáng Hán Ngõa, màu xanh Lục Nê, dung tích 240ml, không dùng điện, không hiệu, NSX: Shenzhen Tao Hui Industrial Co., Ltd., Mới 100% | D6: ='HỢP ĐỒNG'!I23 -> 69120000 | E6: CN | F6: ='HỢP ĐỒNG'!E23 -> 10 | G6: ='INVOICE lam CO'!D19 -> PCE | H6: 10 | I6: PCE | J6: ='HỢP ĐỒNG'!F23 -> 13.6 | M6: B05 | Y6: =IF(Z6=8%,"VB245",IF(Z6=10%,"VB901",IF(Z6=5%,"VB185",""))) -> VB245 | Z6: ='HỢP ĐỒNG'!P23 -> 0.08
A7: ='HỢP ĐỒNG'!A24 -> 6 | C7: ='HỢP ĐỒNG'!C24 -> Ấm pha trà bằng gốm đất nung không tráng men (Tử Sa) dáng Tây Thi, màu đỏ Đại Hồng Bào, dung tích 240ml, không dùng điện, không hiệu, NSX: Shenzhen Tao Hui Industrial Co., Ltd., Mới 100% | D7: ='HỢP ĐỒNG'!I24 -> 69120000 | E7: CN | F7: ='HỢP ĐỒNG'!E24 -> 15 | G7: ='INVOICE lam CO'!D20 -> PCE | H7: 15 | I7: PCE | J7: ='HỢP ĐỒNG'!F24 -> 10.46 | M7: B05 | Y7: =IF(Z7=8%,"VB245",IF(Z7=10%,"VB901",IF(Z7=5%,"VB185",""))) -> VB245 | Z7: ='HỢP ĐỒNG'!P24 -> 0.08
A8: ='HỢP ĐỒNG'!A25 -> 7 | C8: ='HỢP ĐỒNG'!C25 -> Cốc uống trà bằng gốm đất nung không tráng men (Tử Sa) họa tiết Thiên Hương, dung tích 180ml, không hiệu, NSX: Shenzhen Tao Hui Industrial Co., Ltd., Mới 100% | D8: ='HỢP ĐỒNG'!I25 -> 69120000 | E8: CN | F8: ='HỢP ĐỒNG'!E25 -> 20 | G8: ='INVOICE lam CO'!D21 -> PCE | H8: 20 | I8: PCE | J8: ='HỢP ĐỒNG'!F25 -> 4.49 | M8: B05 | Y8: =IF(Z8=8%,"VB245",IF(Z8=10%,"VB901",IF(Z8=5%,"VB185",""))) -> VB245 | Z8: ='HỢP ĐỒNG'!P25 -> 0.08
A9: ='HỢP ĐỒNG'!A26 -> 8 | C9: ='HỢP ĐỒNG'!C26 -> Ấm pha trà bằng gốm đất nung không tráng men (Tử Sa) dáng Bát Phương Nung Củi, màu vàng Đoạn Nê, dung tích 270ml, không dùng điện, không hiệu, NSX: Shenzhen Tao Hui Industrial Co., Ltd., Mới 100% | D9: ='HỢP ĐỒNG'!I26 -> 69120000 | E9: CN | F9: ='HỢP ĐỒNG'!E26 -> 10 | G9: ='INVOICE lam CO'!D22 -> PCE | H9: 10 | I9: PCE | J9: ='HỢP ĐỒNG'!F26 -> 16.74 | M9: B05 | Y9: =IF(Z9=8%,"VB245",IF(Z9=10%,"VB901",IF(Z9=5%,"VB185",""))) -> VB245 | Z9: ='HỢP ĐỒNG'!P26 -> 0.08
A10: ='HỢP ĐỒNG'!A27 -> 9 | C10: ='HỢP ĐỒNG'!C27 -> Ấm pha trà bằng gốm đất nung không tráng men (Tử Sa) dáng Thạch Biều, màu xanh Lục Nê, dung tích 260ml, không dùng điện, không hiệu, NSX: Shenzhen Tao Hui Industrial Co., Ltd., Mới 100% | D10: ='HỢP ĐỒNG'!I27 -> 69120000 | E10: CN | F10: ='HỢP ĐỒNG'!E27 -> 5 | G10: ='INVOICE lam CO'!D23 -> PCE | H10: 5 | I10: PCE | J10: ='HỢP ĐỒNG'!F27 -> 15.69 | M10: B05 | Y10: =IF(Z10=8%,"VB245",IF(Z10=10%,"VB901",IF(Z10=5%,"VB185",""))) -> VB245 | Z10: ='HỢP ĐỒNG'!P27 -> 0.08
A11: ='HỢP ĐỒNG'!A28 -> 10 | C11: ='HỢP ĐỒNG'!C28 -> Ấm pha trà bằng gốm đất nung không tráng men (Tử Sa) dáng Vân Lư, màu nâu Thiết Huyết Hồng Sa, dung tích 260ml, không dùng điện, không hiệu, NSX: Shenzhen Tao Hui Industrial Co., Ltd., Mới 100% | D11: ='HỢP ĐỒNG'!I28 -> 69120000 | E11: CN | F11: ='HỢP ĐỒNG'!E28 -> 10 | G11: ='INVOICE lam CO'!D24 -> PCE | H11: 10 | I11: PCE | J11: ='HỢP ĐỒNG'!F28 -> 17.09 | M11: B05 | Y11: =IF(Z11=8%,"VB245",IF(Z11=10%,"VB901",IF(Z11=5%,"VB185",""))) -> VB245 | Z11: ='HỢP ĐỒNG'!P28 -> 0.08
A12: ='HỢP ĐỒNG'!A29 -> 11 | C12: ='HỢP ĐỒNG'!C29 -> Ấm pha trà bằng gốm đất nung không tráng men (Tử Sa) dáng Tứ Phương Liên Hoa dung tích 230ml, không dùng điện, không hiệu, NSX: Shenzhen Tao Hui Industrial Co., Ltd., Mới 100% | D12: ='HỢP ĐỒNG'!I29 -> 69120000 | E12: CN | F12: ='HỢP ĐỒNG'!E29 -> 10 | G12: ='INVOICE lam CO'!D25 -> PCE | H12: 10 | I12: PCE | J12: ='HỢP ĐỒNG'!F29 -> 14.47 | M12: B05 | Y12: =IF(Z12=8%,"VB245",IF(Z12=10%,"VB901",IF(Z12=5%,"VB185",""))) -> VB245 | Z12: ='HỢP ĐỒNG'!P29 -> 0.08
A13: ='HỢP ĐỒNG'!A30 -> 12 | C13: ='HỢP ĐỒNG'!C30 -> Ấm pha trà bằng gốm đất nung không tráng men (Tử Sa) dáng Long Đán, màu nâu Tử Nê, dung tích 220ml, không dùng điện, không hiệu, NSX: Shenzhen Tao Hui Industrial Co., Ltd., Mới 100% | D13: ='HỢP ĐỒNG'!I30 -> 69120000 | E13: CN | F13: ='HỢP ĐỒNG'!E30 -> 3 | G13: ='INVOICE lam CO'!D26 -> PCE | H13: 3 | I13: PCE | J13: ='HỢP ĐỒNG'!F30 -> 20.46 | M13: B05 | Y13: =IF(Z13=8%,"VB245",IF(Z13=10%,"VB901",IF(Z13=5%,"VB185",""))) -> VB245 | Z13: ='HỢP ĐỒNG'!P30 -> 0.08
... A100: ='HỢP ĐỒNG'!A117 -> 99 | C100: ='HỢP ĐỒNG'!C117 -> Điều khiển điều hòa từ xa, điều khiển bằng sóng hồng ngoại, vỏ bằng nhựa PVC. Không hiệu. Nsx: Shanghai shanghua electronic Co.,Ltd. Mới 100% | D100: ='HỢP ĐỒNG'!I117 -> 85437029 | E100: CN | F100: ='HỢP ĐỒNG'!E117 -> 3450 | G100: ='INVOICE lam CO'!D113 -> PCE | H100: 3450 | I100: PCE | J100: ='HỢP ĐỒNG'!F117 -> 0.57 | M100: B05 | Y100: =IF(Z100=8%,"VB245",IF(Z100=10%,"VB901",IF(Z100=5%,"VB185",""))) -> VB245 | Z100: ='HỢP ĐỒNG'!P117 -> 0.08
A101: ='HỢP ĐỒNG'!A118 -> 100 | C101: ='HỢP ĐỒNG'!C118 -> Máy cưa bê tông đĩa tròn cầm tay không chổi than model K6006, hoạt động bằng điện, đ/a: 220V, cs: 55W, tốc độ: 2700 vòng/p, không hiệu,NSX: Ningbo zhihao machinery. Mới 100% | D101: ='HỢP ĐỒNG'!I118 -> 84672900 | E101: CN | F101: ='HỢP ĐỒNG'!E118 -> 16 | G101: UNK | H101: 16 | I101: PCE | J101: ='HỢP ĐỒNG'!F118 -> 30.16 | M101: B05 | Y101: =IF(Z101=8%,"VB245",IF(Z101=10%,"VB901",IF(Z101=5%,"VB185",""))) -> VB245 | Z101: ='HỢP ĐỒNG'!P118 -> 0.08
A102: ='HỢP ĐỒNG'!A119 -> 101 | C102: ='HỢP ĐỒNG'!C119 -> Đèn chiếu sáng trang trí bể cá cảnh, Model:DY-A200, sử dụng nguồn sáng đi ốt phát quang (LED) không phải loại quang điện. KT: 20*15*8cm. CS: 18W/220V. Hiệu:DEYAO. Mới 100% | D102: ='HỢP ĐỒNG'!I119 -> 94054290 | E102: CN | F102: ='HỢP ĐỒNG'!E119 -> 120 | G102: UNK | H102: 120 | I102: PCE | J102: ='HỢP ĐỒNG'!F119 -> 2.07 | M102: B05 | Y102: =IF(Z102=8%,"VB245",IF(Z102=10%,"VB901",IF(Z102=5%,"VB185",""))) -> VB245 | Z102: ='HỢP ĐỒNG'!P119 -> 0.08
A103: ='HỢP ĐỒNG'!A120 -> 102 | C103: ='HỢP ĐỒNG'!C120 -> Đèn chiếu sáng trang trí bể cá cảnh, Model:DY-A300, sử dụng nguồn sáng đi ốt phát quang (LED) không phải loại quang điện. KT: 30*15*8cm. CS: 22W/220V. Hiệu:DEYAO. Mới 100% | D103: ='HỢP ĐỒNG'!I120 -> 94054290 | E103: CN | F103: ='HỢP ĐỒNG'!E120 -> 160 | G103: UNK | H103: 160 | I103: PCE | J103: ='HỢP ĐỒNG'!F120 -> 2.26 | M103: B05 | Y103: =IF(Z103=8%,"VB245",IF(Z103=10%,"VB901",IF(Z103=5%,"VB185",""))) -> VB245 | Z103: ='HỢP ĐỒNG'!P120 -> 0.08
A104: ='HỢP ĐỒNG'!A121 -> 103 | C104: ='HỢP ĐỒNG'!C121 -> Đèn chiếu sáng trang trí bể cá cảnh, Model:DY-A400, sử dụng nguồn sáng đi ốt phát quang (LED) không phải loại quang điện. KT: 40*15*8cm. CS: 28W/220V. Hiệu:DEYAO. Mới 100% | D104: ='HỢP ĐỒNG'!I121 -> 94054290 | E104: CN | F104: ='HỢP ĐỒNG'!E121 -> 200 | G104: ='INVOICE lam CO'!D117 -> PCE | H104: 200 | I104: PCE | J104: ='HỢP ĐỒNG'!F121 -> 2.45 | M104: B05 | Y104: =IF(Z104=8%,"VB245",IF(Z104=10%,"VB901",IF(Z104=5%,"VB185",""))) -> VB245 | Z104: ='HỢP ĐỒNG'!P121 -> 0.08
A105: ='HỢP ĐỒNG'!A122 -> 104 | C105: ='HỢP ĐỒNG'!C122 -> Đèn chiếu sáng trang trí bể cá cảnh, Model:DY-A500, sử dụng nguồn sáng đi ốt phát quang (LED) không phải loại quang điện. KT: 50*15*8cm. CS: 34W/220V. Hiệu:DEYAO. Mới 100% | D105: ='HỢP ĐỒNG'!I122 -> 94054290 | E105: CN | F105: ='HỢP ĐỒNG'!E122 -> 600 | G105: ='INVOICE lam CO'!D118 -> PCE | H105: 600 | I105: PCE | J105: ='HỢP ĐỒNG'!F122 -> 2.64 | M105: B05 | Y105: =IF(Z105=8%,"VB245",IF(Z105=10%,"VB901",IF(Z105=5%,"VB185",""))) -> VB245 | Z105: ='HỢP ĐỒNG'!P122 -> 0.08
A106: ='HỢP ĐỒNG'!A123 -> 105 | C106: ='HỢP ĐỒNG'!C123 -> Đèn chiếu sáng trang trí bể cá cảnh, Model:DY-A600, sử dụng nguồn sáng đi ốt phát quang (LED) không phải loại quang điện. KT: 60*15*8cm. CS: 38W/220V. Hiệu:DEYAO. Mới 100% | D106: ='HỢP ĐỒNG'!I123 -> 94054290 | E106: CN | F106: ='HỢP ĐỒNG'!E123 -> 800 | G106: ='INVOICE lam CO'!D119 -> PCE | H106: 800 | I106: PCE | J106: ='HỢP ĐỒNG'!F123 -> 2.83 | M106: B05 | Y106: =IF(Z106=8%,"VB245",IF(Z106=10%,"VB901",IF(Z106=5%,"VB185",""))) -> VB245 | Z106: ='HỢP ĐỒNG'!P123 -> 0.08
A107: ='HỢP ĐỒNG'!A124 -> 106 | C107: ='HỢP ĐỒNG'!C124 -> Đèn chiếu sáng trang trí bể cá cảnh, Model:DY-A800, sử dụng nguồn sáng đi ốt phát quang (LED) không phải loại quang điện. KT: 80*15*8cm. CS: 46W/220V. Hiệu:DEYAO. Mới 100% | D107: ='HỢP ĐỒNG'!I124 -> 94054290 | E107: CN | F107: ='HỢP ĐỒNG'!E124 -> 600 | G107: UNK | H107: 600 | I107: PCE | J107: ='HỢP ĐỒNG'!F124 -> 3.02 | M107: B05 | Y107: =IF(Z107=8%,"VB245",IF(Z107=10%,"VB901",IF(Z107=5%,"VB185",""))) -> VB245 | Z107: ='HỢP ĐỒNG'!P124 -> 0.08
A108: ='HỢP ĐỒNG'!A125 -> 107 | C108: ='HỢP ĐỒNG'!C125 -> Đèn chiếu sáng trang trí bể cá cảnh, Model:DY-A1000, sử dụng nguồn sáng đi ốt phát quang (LED) không phải loại quang điện. KT: 100*15*8cm. CS: 55W/220V. Hiệu:DEYAO. Mới 100% | D108: ='HỢP ĐỒNG'!I125 -> 94054290 | E108: CN | F108: ='HỢP ĐỒNG'!E125 -> 400 | G108: UNK | H108: 400 | I108: PCE | J108: ='HỢP ĐỒNG'!F125 -> 3.2 | M108: B05 | Y108: =IF(Z108=8%,"VB245",IF(Z108=10%,"VB901",IF(Z108=5%,"VB185",""))) -> VB245 | Z108: ='HỢP ĐỒNG'!P125 -> 0.08
A109: ='HỢP ĐỒNG'!A126 -> 108 | C109: ='HỢP ĐỒNG'!C126 -> Đèn chiếu sáng trang trí bể cá cảnh, Model: E23, sử dụng nguồn sáng đi ốt phát quang (LED) không phải loại quang điện. KT: 30*10*8cm. Công suất:12w/220V. Hiệu:DEYAO. Mới 100% | D109: ='HỢP ĐỒNG'!I126 -> 94054290 | E109: CN | F109: ='HỢP ĐỒNG'!E126 -> 250 | G109: UNK | H109: 250 | I109: PCE | J109: ='HỢP ĐỒNG'!F126 -> 2.26 | M109: B05 | Y109: =IF(Z109=8%,"VB245",IF(Z109=10%,"VB901",IF(Z109=5%,"VB185",""))) -> VB245 | Z109: ='HỢP ĐỒNG'!P126 -> 0.08
A110: ='HỢP ĐỒNG'!A127 -> 109 | C110: ='HỢP ĐỒNG'!C127 -> Đèn chiếu sáng trang trí bể cá cảnh, Model:E29 , sử dụng nguồn sáng đi ốt phát quang (LED) không phải loại quang điện. KT: 40*10*8cm. Công suất:16w/220V. Hiệu:DEYAO. Mới 100% | D110: ='HỢP ĐỒNG'!I127 -> 94054290 | E110: CN | F110: ='HỢP ĐỒNG'!E127 -> 250 | G110: UNK | H110: 250 | I110: PCE | J110: ='HỢP ĐỒNG'!F127 -> 2.64 | M110: B05 | Y110: =IF(Z110=8%,"VB245",IF(Z110=10%,"VB901",IF(Z110=5%,"VB185",""))) -> VB245 | Z110: ='HỢP ĐỒNG'!P127 -> 0.08
A111: ='HỢP ĐỒNG'!A128 -> 110 | C111: ='HỢP ĐỒNG'!C128 -> Đèn chiếu sáng trang trí bể cá cảnh, Model: E39, sử dụng nguồn sáng đi ốt phát quang (LED) không phải loại quang điện. KT: 40*10*8cm. Công suất:20w/220V. Hiệu:DEYAO. Mới 100% | D111: ='HỢP ĐỒNG'!I128 -> 94054290 | E111: CN | F111: ='HỢP ĐỒNG'!E128 -> 250 | G111: UNK | H111: 250 | I111: PCE | J111: ='HỢP ĐỒNG'!F128 -> 3.02 | M111: B05 | Y111: =IF(Z111=8%,"VB245",IF(Z111=10%,"VB901",IF(Z111=5%,"VB185",""))) -> VB245 | Z111: ='HỢP ĐỒNG'!P128 -> 0.08
A112: ='HỢP ĐỒNG'!A129 -> 111 | C112: ='HỢP ĐỒNG'!C129 -> Đèn chiếu sáng trang trí bể cá cảnh, Model: E49 , sử dụng nguồn sáng đi ốt phát quang (LED) không phải loại quang điện. KT: 40*10*8cm. Công suất:24w/220V. Hiệu:DEYAO. Mới 100% | D112: ='HỢP ĐỒNG'!I129 -> 94054290 | E112: CN | F112: ='HỢP ĐỒNG'!E129 -> 250 | G112: UNK | H112: 250 | I112: PCE | J112: ='HỢP ĐỒNG'!F129 -> 3.39 | M112: B05 | Y112: =IF(Z112=8%,"VB245",IF(Z112=10%,"VB901",IF(Z112=5%,"VB185",""))) -> VB245 | Z112: ='HỢP ĐỒNG'!P129 -> 0.08
A113: ='HỢP ĐỒNG'!A130 -> 112 | C113: ='HỢP ĐỒNG'!C130 -> Đèn chiếu sáng trang trí bể cá cảnh, Model:CF02, sử dụng nguồn sáng đi ốt phát quang (LED), không phải loại quang điện. KT: 18*15*6cm.Công suất: 13W-220V. Hiệu:DEYAO. Mới 100% | D113: ='HỢP ĐỒNG'!I130 -> 94054290 | E113: CN | F113: ='HỢP ĐỒNG'!E130 -> 2000 | G113: UNK | H113: 2000 | I113: PCE | J113: ='HỢP ĐỒNG'!F130 -> 2.07 | M113: B05 | Y113: =IF(Z113=8%,"VB245",IF(Z113=10%,"VB901",IF(Z113=5%,"VB185",""))) -> VB245 | Z113: ='HỢP ĐỒNG'!P130 -> 0.08
A114: ='HỢP ĐỒNG'!A131 -> 113 | C114: ='HỢP ĐỒNG'!C131 -> Đèn chiếu sáng trang trí bể cá cảnh, Model:F-01, sử dụng nguồn sáng đi ốt phát quang (LED), không phải loại quang điện KT: 35*15*10cm.Công suất: 12W-220V. Hiệu:DEYAO. Mới 100% | D114: ='HỢP ĐỒNG'!I131 -> 94054290 | E114: CN | F114: ='HỢP ĐỒNG'!E131 -> 300 | G114: UNK | H114: 300 | I114: PCE | J114: ='HỢP ĐỒNG'!F131 -> 2.64 | M114: B05 | Y114: =IF(Z114=8%,"VB245",IF(Z114=10%,"VB901",IF(Z114=5%,"VB185",""))) -> VB245 | Z114: ='HỢP ĐỒNG'!P131 -> 0.08
A115: ='HỢP ĐỒNG'!A132 -> 114 | C115: ='HỢP ĐỒNG'!C132 -> Đèn chiếu sáng trang trí bể cá cảnh, Model:F-07, sử dụng nguồn sáng đi ốt phát quang (LED), không phải loại quang điện. KT: 35*15*10cm.Công suất: 20W-220V. Hiệu:DEYAO. Mới 100% | D115: ='HỢP ĐỒNG'!I132 -> 94054290 | E115: CN | F115: ='HỢP ĐỒNG'!E132 -> 250 | G115: UNK | H115: 250 | I115: PCE | J115: ='HỢP ĐỒNG'!F132 -> 3.39 | M115: B05 | Y115: =IF(Z115=8%,"VB245",IF(Z115=10%,"VB901",IF(Z115=5%,"VB185",""))) -> VB245 | Z115: ='HỢP ĐỒNG'!P132 -> 0.08
A116: ='HỢP ĐỒNG'!A133 -> 115 | C116: ='HỢP ĐỒNG'!C133 -> Đèn chiếu sáng trang trí bể cá cảnh, Model:F-09, sử dụng nguồn sáng đi ốt phát quang (LED, không phải loại quang điện. KT: 35*15*10cm.Công suất: 15W-220V. Hiệu:DEYAO. Mới 100% | D116: ='HỢP ĐỒNG'!I133 -> 94054290 | E116: CN | F116: ='HỢP ĐỒNG'!E133 -> 400 | G116: UNK | H116: 400 | I116: PCE | J116: ='HỢP ĐỒNG'!F133 -> 4.9 | M116: B05 | Y116: =IF(Z116=8%,"VB245",IF(Z116=10%,"VB901",IF(Z116=5%,"VB185",""))) -> VB245 | Z116: ='HỢP ĐỒNG'!P133 -> 0.08
A117: ='HỢP ĐỒNG'!A134 -> 116 | C117: ='HỢP ĐỒNG'!C134 -> Hộp giấy bìa không sóng có thể gấp lại dùng để đóng gói, vận chuyển hoa sáp, KT: 46*24*8cm+-10%, không hiệu. Nsx: Guangdong Daming Decoration Co., Ltd, Mới 100% | D117: ='HỢP ĐỒNG'!I134 -> 48192000 | E117: CN | F117: ='HỢP ĐỒNG'!E134 -> 400 | G117: ='INVOICE lam CO'!D130 -> KGM | H117: 400 | I117: KGM | J117: ='HỢP ĐỒNG'!F134 -> 0.8 | M117: B01 | Y117: =IF(Z117=8%,"VB245",IF(Z117=10%,"VB901",IF(Z117=5%,"VB185",""))) -> VB245 | Z117: ='HỢP ĐỒNG'!P134 -> 0.08
A118: ='HỢP ĐỒNG'!A135 -> 117 | C118: ='HỢP ĐỒNG'!C135 -> Khay nhựa PVC định hình bóng khí, dùng lót đáy hộp quà tặng khi đóng gói vận chuyển, chất liệu nhựa PVC, KT: 44*22*3.1cm+-10%, không hiệu. Nsx: Guangdong Daming Decoration Co., Ltd, Mới 100% | D118: ='HỢP ĐỒNG'!I135 -> 39239090 | E118: CN | F118: ='HỢP ĐỒNG'!E135 -> 100 | G118: ='INVOICE lam CO'!D131 -> KGM | H118: 100 | I118: KGM | J118: ='HỢP ĐỒNG'!F135 -> 1.3 | M118: B05 | Y118: =IF(Z118=8%,"VB245",IF(Z118=10%,"VB901",IF(Z118=5%,"VB185",""))) -> VB245 | Z118: ='HỢP ĐỒNG'!P135 -> 0.08
A119: ='HỢP ĐỒNG'!A136 -> 118 | C119: ='HỢP ĐỒNG'!C136 -> Giày bốt trẻ em cổ cao quá mắt cá chân, không đúc, đế bằng cao su mềm, mũ giày bằng nhựa giả da, mũi không gắn bảo vệ, size 22-31. KH:D509, không hiệu. NSX:Jinjiang Anao Footwear Co.,Ltd. mới 100% | D119: ='HỢP ĐỒNG'!I136 -> 64029199 | E119: CN | F119: ='HỢP ĐỒNG'!E136 -> 200 | G119: ='INVOICE lam CO'!D132 -> PR | H119: 200 | I119: PR | J119: ='HỢP ĐỒNG'!F136 -> 1.13 | M119: B05 | Y119: =IF(Z119=8%,"VB245",IF(Z119=10%,"VB901",IF(Z119=5%,"VB185",""))) -> VB245 | Z119: ='HỢP ĐỒNG'!P136 -> 0.08
A120: ='HỢP ĐỒNG'!A137 -> 119 | C120: ='HỢP ĐỒNG'!C137 -> Trạm mồi chống mối nổi kèm phụ kiện lắp đặt, không thấm tẩm hóa chất, chất liệu bằng nhựa tổng hợp, KT: 16.5*8.5*6.5cm+-10%, không hiệu. NSX: Shenzhen iPest Technology Co., Ltd. mới 100% | D120: ='HỢP ĐỒNG'!I137 -> 39269099 | E120: CN | F120: ='HỢP ĐỒNG'!E137 -> 500 | G120: ='INVOICE lam CO'!D133 -> SET | H120: 500 | I120: SET | J120: ='HỢP ĐỒNG'!F137 -> 0.89 | M120: B05 | Y120: =IF(Z120=8%,"VB245",IF(Z120=10%,"VB901",IF(Z120=5%,"VB185",""))) -> VB245 | Z120: ='HỢP ĐỒNG'!P137 -> 0.08
A121: ='HỢP ĐỒNG'!A138 -> 120 | C121: ='HỢP ĐỒNG'!C138 -> Bánh xe treo cửa thang máy, chất liệu bằng thép không gỉ. KT: (56*14)mm, model: 6201RS, không hiệu. NSX: Tiyou Elevator Parts. Mới 100% | D121: ='HỢP ĐỒNG'!I138 -> 84313120 | E121: CN | F121: ='HỢP ĐỒNG'!E138 -> 200 | G121: ='INVOICE lam CO'!D134 -> PCE | H121: 200 | I121: PCE | J121: ='HỢP ĐỒNG'!F138 -> 1.39 | M121: B05 | Y121: =IF(Z121=8%,"VB245",IF(Z121=10%,"VB901",IF(Z121=5%,"VB185",""))) -> VB245 | Z121: ='HỢP ĐỒNG'!P138 -> 0.08
A122: ='HỢP ĐỒNG'!A139 -> 121 | C122: ='HỢP ĐỒNG'!C139 -> Bánh xe treo cửa thang máy, rãnh phẳng, chất liệu bằng thép không gỉ. KT: (62*16)mm, model: 6203, không hiệu. NSX: Tiyou Elevator Parts. Mới 100% | D122: ='HỢP ĐỒNG'!I139 -> 84313120 | E122: CN | F122: ='HỢP ĐỒNG'!E139 -> 150 | G122: ='INVOICE lam CO'!D135 -> PCE | H122: 150 | I122: PCE | J122: ='HỢP ĐỒNG'!F139 -> 2.07 | M122: B05 | Y122: =IF(Z122=8%,"VB245",IF(Z122=10%,"VB901",IF(Z122=5%,"VB185",""))) -> VB245 | Z122: ='HỢP ĐỒNG'!P139 -> 0.08
A123: ='HỢP ĐỒNG'!A140 -> 122 | C123: ='HỢP ĐỒNG'!C140 -> Bông hoa tuylip nhân tạo, chất liệu nhựa PVC, lõi bằng thép, đã định hình hoàn chỉnh, dùng để trang trí. KT: (35*4)cm+/-10%, không hiệu. NSX: Yuchen Artificial Flower Strength Supplier, mới 100% | D123: ='HỢP ĐỒNG'!I140 -> 67029090 | E123: CN | F123: ='HỢP ĐỒNG'!E140 -> 10000 | G123: ='INVOICE lam CO'!D136 -> PCE | H123: 105 | I123: KGM | J123: ='HỢP ĐỒNG'!F140 -> 0.075 | M123: B05 | Y123: =IF(Z123=8%,"VB245",IF(Z123=10%,"VB901",IF(Z123=5%,"VB185",""))) -> VB245 | Z123: ='HỢP ĐỒNG'!P140 -> 0.08
A124: ='HỢP ĐỒNG'!A141 -> 123 | C124: ='HỢP ĐỒNG'!C141 -> Giấy gói hoa dạng giấy nhún, được làm từ bột gỗ xenlulo, đã nhuộm màu bề mặt, dạng tấm, KT: (50*230)cm+/-10%, không hiệu. Nsx: Jiangxi Yuanna Packaging Material Co., Ltd. Mới 100% | D124: ='HỢP ĐỒNG'!I141 -> 48119093 | E124: CN | F124: ='HỢP ĐỒNG'!E141 -> 398 | G124: ='INVOICE lam CO'!D137 -> KGM | H124: 398 | I124: KGM | J124: ='HỢP ĐỒNG'!F141 -> 0.8 | M124: B05 | Y124: =IF(Z124=8%,"VB245",IF(Z124=10%,"VB901",IF(Z124=5%,"VB185",""))) -> VB245 | Z124: ='HỢP ĐỒNG'!P141 -> 0.08
A125: ='HỢP ĐỒNG'!A142 -> 124 | C125: ='HỢP ĐỒNG'!C142 -> Máy phun sơn tĩnh điện dùng để phun sơn hoàn thiện bề mặt các sản phẩm bằng kim loại,kèm khung đỡ có bánh xe.Model:FlexiSpray F1,điện áp:AC100-240,CS: 50W. NSX: Foshan Debelle Technology,mới 100% | D125: ='HỢP ĐỒNG'!I142 -> 84242029 | E125: CN | F125: ='HỢP ĐỒNG'!E142 -> 2 | G125: ='INVOICE lam CO'!D138 -> PCE | H125: 2 | I125: PCE | J125: ='HỢP ĐỒNG'!F142 -> 1884.87 | M125: B05 | Y125: =IF(Z125=8%,"VB245",IF(Z125=10%,"VB901",IF(Z125=5%,"VB185",""))) -> VB245 | Z125: ='HỢP ĐỒNG'!P142 -> 0.08

Sheet INVOICE lam CO
A1: INVOICE
B3: INVOICE NO: | C3: =INVOICE!F4 -> 0902 GF-TH/26
B4: DATE: | C4: =INVOICE!F5 -> 46271
A6: BUYER: TRUONG HAI TRADING AND IMPORT-EXPORT COMPANY LIMITED
A7: Address: No. 12, Secondary Road No. 4, Phu Loc 2 Urban Area, Ky Lua Ward, Lang Son Province, Vietnam.
A9: TRANSPORT: BY TRUCK
A11: FROM : CHINA: VIA TANTHANH | C11: BORDER GATE :
E12: DAF TAN THANH - VIET NAM
A14: N0 | B14: Description of good | C14: HS code | D14: Unit | E14: Q.ty | F14: Unit price (USD) | G14: Amount (USD) | H14: Số kiện
